<sdf version='1.7'>
  <world name='default'>
    <light name='sun' type='directional'>
      <cast_shadows>1</cast_shadows>
      <pose>0 0 10 0 -0 0</pose>
      <diffuse>0.8 0.8 0.8 1</diffuse>
      <specular>0.2 0.2 0.2 1</specular>
      <attenuation>
        <range>1000</range>
        <constant>0.9</constant>
        <linear>0.01</linear>
        <quadratic>0.001</quadratic>
      </attenuation>
      <direction>-0.5 0.1 -0.9</direction>
      <spot>
        <inner_angle>0</inner_angle>
        <outer_angle>0</outer_angle>
        <falloff>0</falloff>
      </spot>
    </light>
    <model name='ground_plane'>
      <static>1</static>
      <link name='link'>
        <collision name='collision'>
          <geometry>
            <plane>
              <normal>0 0 1</normal>
              <size>100 100</size>
            </plane>
          </geometry>
          <surface>
            <contact>
              <collide_bitmask>65535</collide_bitmask>
              <ode/>
            </contact>
            <friction>
              <ode>
                <mu>100</mu>
                <mu2>50</mu2>
              </ode>
              <torsional>
                <ode/>
              </torsional>
            </friction>
            <bounce/>
          </surface>
          <max_contacts>10</max_contacts>
        </collision>
        <visual name='visual'>
          <cast_shadows>0</cast_shadows>
          <geometry>
            <plane>
              <normal>0 0 1</normal>
              <size>100 100</size>
            </plane>
          </geometry>
          <material>
            <script>
              <uri>file://media/materials/scripts/gazebo.material</uri>
              <name>Gazebo/Grey</name>
            </script>
          </material>
        </visual>
        <self_collide>0</self_collide>
        <enable_wind>0</enable_wind>
        <kinematic>0</kinematic>
      </link>
    </model>
    <gravity>0 0 -9.8</gravity>
    <magnetic_field>6e-06 2.3e-05 -4.2e-05</magnetic_field>
    <atmosphere type='adiabatic'/>
    <physics type='ode'>
      <max_step_size>0.001</max_step_size>
      <real_time_factor>1</real_time_factor>
      <real_time_update_rate>1000</real_time_update_rate>
    </physics>
    <scene>
      <ambient>0.4 0.4 0.4 1</ambient>
      <background>0.7 0.7 0.7 1</background>
      <shadows>1</shadows>
    </scene>
    <wind/>
    <spherical_coordinates>
      <surface_model>EARTH_WGS84</surface_model>
      <latitude_deg>0</latitude_deg>
      <longitude_deg>0</longitude_deg>
      <elevation>0</elevation>
      <heading_deg>0</heading_deg>
    </spherical_coordinates>
    <model name='tiago'>
      <link name='base_footprint'>
        <inertial>
          <pose>-0.00978 -0.00152 0.213783 0 -0 0</pose>
          <mass>42.8506</mass>
          <inertia>
            <ixx>2.01958</ixx>
            <ixy>0.00074088</ixy>
            <ixz>0.109957</ixz>
            <iyy>2.0976</iyy>
            <iyz>0.0139293</iyz>
            <izz>0.666852</izz>
          </inertia>
        </inertial>
        <collision name='base_footprint_fixed_joint_lump__base_link_collision'>
          <pose>0 0 0.0985 0 -0 0</pose>
          <geometry>
            <mesh>
              <scale>1 1 1</scale>
              <uri>/opt/tiago_public_ws/src/pmb2_robot/pmb2_description/meshes/base/base_collision.stl</uri>
            </mesh>
          </geometry>
          <surface>
            <contact>
              <ode/>
            </contact>
            <friction>
              <ode/>
              <torsional>
                <ode/>
              </torsional>
            </friction>
            <bounce/>
          </surface>
          <max_contacts>10</max_contacts>
        </collision>
        <collision name='base_footprint_fixed_joint_lump__base_antenna_left_link_collision_1'>
          <pose>-0.201 0.1062 0.3785 0 -0 0</pose>
          <geometry>
            <cylinder>
              <length>0.17</length>
              <radius>0.005</radius>
            </cylinder>
          </geometry>
          <surface>
            <contact>
              <ode/>
            </contact>
            <friction>
              <ode/>
              <torsional>
                <ode/>
              </torsional>
            </friction>
            <bounce/>
          </surface>
          <max_contacts>10</max_contacts>
        </collision>
        <collision name='base_footprint_fixed_joint_lump__base_antenna_right_link_collision_2'>
          <pose>-0.201 -0.1062 0.3785 0 -0 0</pose>
          <geometry>
            <cylinder>
              <length>0.17</length>
              <radius>0.005</radius>
            </cylinder>
          </geometry>
          <surface>
            <contact>
              <ode/>
            </contact>
            <friction>
              <ode/>
              <torsional>
                <ode/>
              </torsional>
            </friction>
            <bounce/>
          </surface>
          <max_contacts>10</max_contacts>
        </collision>
        <collision name='base_footprint_fixed_joint_lump__base_laser_link_collision_3'>
          <pose>0.202 0 0.0945 0 -0 0</pose>
          <geometry>
            <cylinder>
              <length>0.04</length>
              <radius>0.02</radius>
            </cylinder>
          </geometry>
          <surface>
            <contact>
              <ode/>
            </contact>
            <friction>
              <ode/>
              <torsional>
                <ode/>
              </torsional>
            </friction>
            <bounce/>
          </surface>
          <max_contacts>10</max_contacts>
        </collision>
        <collision name='base_footprint_fixed_joint_lump__torso_fixed_column_link_collision_4'>
          <pose>-0.062 0 0.5685 0 -0 0</pose>
          <geometry>
            <box>
              <size>0.23 0.253 0.45</size>
            </box>
          </geometry>
          <surface>
            <contact>
              <ode/>
            </contact>
            <friction>
              <ode/>
              <torsional>
                <ode/>
              </torsional>
            </friction>
            <bounce/>
          </surface>
          <max_contacts>10</max_contacts>
        </collision>
        <collision name='base_footprint_fixed_joint_lump__torso_fixed_link_collision_5'>
          <pose>0.023 0 0.3115 0 -0 0</pose>
          <geometry>
            <box>
              <size>0.4 0.265 0.05</size>
            </box>
          </geometry>
          <max_contacts>10</max_contacts>
          <surface>
            <contact>
              <ode/>
            </contact>
            <bounce/>
            <friction>
              <torsional>
                <ode/>
              </torsional>
              <ode/>
            </friction>
          </surface>
        </collision>
        <collision name='base_footprint_fixed_joint_lump__torso_fixed_link_collision_6'>
          <pose>-0.062 0 0.3415 0 -0 0</pose>
          <geometry>
            <box>
              <size>0.255 0.255 0.117</size>
            </box>
          </geometry>
          <max_contacts>10</max_contacts>
          <surface>
            <contact>
              <ode/>
            </contact>
            <bounce/>
            <friction>
              <torsional>
                <ode/>
              </torsional>
              <ode/>
            </friction>
          </surface>
        </collision>
        <visual name='base_footprint_fixed_joint_lump__base_link_visual'>
          <pose>0 0 0.0985 0 -0 0</pose>
          <geometry>
            <mesh>
              <scale>1 1 1</scale>
              <uri>/opt/tiago_public_ws/src/pmb2_robot/pmb2_description/meshes/base/base.stl</uri>
            </mesh>
          </geometry>
          <material>
            <script>
              <name>Gazebo/White</name>
              <uri>file://media/materials/scripts/gazebo.material</uri>
            </script>
          </material>
        </visual>
        <visual name='base_footprint_fixed_joint_lump__base_antenna_left_link_visual_1'>
          <pose>-0.201 0.1062 0.2935 0 -0 0</pose>
          <geometry>
            <mesh>
              <scale>1 1 1</scale>
              <uri>/opt/tiago_public_ws/src/pmb2_robot/pmb2_description/meshes/objects/antenna.stl</uri>
            </mesh>
          </geometry>
          <material>
            <script>
              <name>Gazebo/Black</name>
              <uri>file://media/materials/scripts/gazebo.material</uri>
            </script>
          </material>
        </visual>
        <visual name='base_footprint_fixed_joint_lump__base_antenna_right_link_visual_2'>
          <pose>-0.201 -0.1062 0.2935 0 -0 0</pose>
          <geometry>
            <mesh>
              <scale>1 1 1</scale>
              <uri>/opt/tiago_public_ws/src/pmb2_robot/pmb2_description/meshes/objects/antenna.stl</uri>
            </mesh>
          </geometry>
          <material>
            <script>
              <name>Gazebo/Black</name>
              <uri>file://media/materials/scripts/gazebo.material</uri>
            </script>
          </material>
        </visual>
        <visual name='base_footprint_fixed_joint_lump__base_laser_link_visual_3'>
          <pose>0.202 0 0.0945 0 -0 0</pose>
          <geometry>
            <mesh>
              <scale>1 1 1</scale>
              <uri>/opt/tiago_public_ws/src/pmb2_robot/pmb2_description/meshes/sensors/sick_tim551.stl</uri>
            </mesh>
          </geometry>
          <material>
            <script>
              <name>Gazebo/DarkGrey</name>
              <uri>file://media/materials/scripts/gazebo.material</uri>
            </script>
          </material>
        </visual>
        <visual name='base_footprint_fixed_joint_lump__base_sonar_01_link_visual_4'>
          <pose>-0.183 -0.183 0.2715 0 0 -2.35619</pose>
          <geometry>
            <mesh>
              <scale>1 1 1</scale>
              <uri>/opt/tiago_public_ws/src/pmb2_robot/pmb2_description/meshes/sensors/srf05.stl</uri>
            </mesh>
          </geometry>
          <material>
            <script>
              <name>Gazebo/DarkGrey</name>
              <uri>file://media/materials/scripts/gazebo.material</uri>
            </script>
          </material>
        </visual>
        <visual name='base_footprint_fixed_joint_lump__base_sonar_02_link_visual_5'>
          <pose>-0.259 0 0.2715 0 -0 3.14159</pose>
          <geometry>
            <mesh>
              <scale>1 1 1</scale>
              <uri>/opt/tiago_public_ws/src/pmb2_robot/pmb2_description/meshes/sensors/srf05.stl</uri>
            </mesh>
          </geometry>
          <material>
            <script>
              <name>Gazebo/DarkGrey</name>
              <uri>file://media/materials/scripts/gazebo.material</uri>
            </script>
          </material>
        </visual>
        <visual name='base_footprint_fixed_joint_lump__base_sonar_03_link_visual_6'>
          <pose>-0.183 0.183 0.2715 0 -0 2.35619</pose>
          <geometry>
            <mesh>
              <scale>1 1 1</scale>
              <uri>/opt/tiago_public_ws/src/pmb2_robot/pmb2_description/meshes/sensors/srf05.stl</uri>
            </mesh>
          </geometry>
          <material>
            <script>
              <name>Gazebo/DarkGrey</name>
              <uri>file://media/materials/scripts/gazebo.material</uri>
            </script>
          </material>
        </visual>
        <visual name='base_footprint_fixed_joint_lump__torso_fixed_column_link_visual_7'>
          <pose>-0.062 0 0.5685 0 -0 0</pose>
          <geometry>
            <box>
              <size>0.18 0.2 0.55</size>
            </box>
          </geometry>
          <material>
            <script>
              <name>Gazebo/DarkGrey</name>
              <uri>file://media/materials/scripts/gazebo.material</uri>
            </script>
          </material>
        </visual>
        <visual name='base_footprint_fixed_joint_lump__torso_fixed_link_visual_8'>
          <pose>-0.062 0 0.2915 0 -0 0</pose>
          <geometry>
            <mesh>
              <scale>1 1 1</scale>
              <uri>/opt/tiago_public_ws/src/tiago_robot/tiago_description/meshes/torso/torso_fix.stl</uri>
            </mesh>
          </geometry>
        </visual>
        <visual name='base_footprint_fixed_joint_lump__base_cover_link_visual_9'>
          <pose>0 0 0.13 0 -0 0</pose>
          <geometry>
            <mesh>
              <scale>1 1 1</scale>
              <uri>/opt/tiago_public_ws/src/pmb2_robot/pmb2_description/meshes/base/base_ring.stl</uri>
            </mesh>
          </geometry>
          <material>
            <script>
              <name>Gazebo/Orange</name>
              <uri>file://media/materials/scripts/gazebo.material</uri>
            </script>
          </material>
        </visual>
        <sensor name='imu_sensor' type='imu'>
          <always_on>1</always_on>
          <update_rate>1000</update_rate>
          <imu>
            <noise>
              <type>gaussian</type>
              <rate>
                <mean>0.0</mean>
                <stddev>2e-4</stddev>
                <bias_mean>0.0000075</bias_mean>
                <bias_stddev>0.0000008</bias_stddev>
              </rate>
              <accel>
                <mean>0.0</mean>
                <stddev>1.7e-2</stddev>
                <bias_mean>0.1</bias_mean>
                <bias_stddev>0.001</bias_stddev>
              </accel>
            </noise>
          </imu>
          <pose>0.10171 0 0.21132 0 0 -1.5708</pose>
        </sensor>
        <sensor name='base_imu_sensor' type='imu'>
          <always_on>1</always_on>
          <update_rate>100</update_rate>
          <imu>
            <noise>
              <type>gaussian</type>
              <rate>
                <mean>0.0</mean>
                <stddev>2e-4</stddev>
                <bias_mean>0.0000075</bias_mean>
                <bias_stddev>0.0000008</bias_stddev>
              </rate>
              <accel>
                <mean>0.0</mean>
                <stddev>1.7e-2</stddev>
                <bias_mean>0.1</bias_mean>
                <bias_stddev>0.001</bias_stddev>
              </accel>
            </noise>
          </imu>
          <pose>0.10171 0 0.21132 0 0 -1.5708</pose>
        </sensor>
        <sensor name='base_laser' type='ray'>
          <update_rate>10</update_rate>
          <visualize>1</visualize>
          <ray>
            <scan>
              <horizontal>
                <samples>666</samples>
                <resolution>1</resolution>
                <min_angle>-1.91986</min_angle>
                <max_angle>1.91986</max_angle>
              </horizontal>
              <vertical>
                <samples>1</samples>
                <min_angle>0</min_angle>
                <max_angle>0</max_angle>
              </vertical>
            </scan>
            <range>
              <min>0.05</min>
              <max>25</max>
              <resolution>0.001</resolution>
            </range>
          </ray>
          <plugin name='gazebo_ros_sick_laser' filename='libgazebo_ros_laser.so'>
            <gaussianNoise>0.06</gaussianNoise>
            <alwaysOn>1</alwaysOn>
            <updateRate>10</updateRate>
            <topicName>scan_raw</topicName>
            <frameName>base_laser_link</frameName>
            <robotNamespace>/</robotNamespace>
          </plugin>
          <pose>0.202 0 0.0945 0 -0 0</pose>
        </sensor>
        <sensor name='base_sonar_01' type='ray'>
          <update_rate>5</update_rate>
          <visualize>0</visualize>
          <ray>
            <scan>
              <horizontal>
                <samples>5</samples>
                <resolution>1</resolution>
                <min_angle>-0.25</min_angle>
                <max_angle>0.25</max_angle>
              </horizontal>
              <vertical>
                <samples>5</samples>
                <resolution>1</resolution>
                <min_angle>-0.25</min_angle>
                <max_angle>0.25</max_angle>
              </vertical>
            </scan>
            <range>
              <min>0.02</min>
              <max>1</max>
              <resolution>0.01</resolution>
            </range>
          </ray>
          <plugin name='gazebo_ros_range' filename='libgazebo_ros_range.so'>
            <gaussianNoise>0.005</gaussianNoise>
            <alwaysOn>1</alwaysOn>
            <updateRate>5</updateRate>
            <topicName>sonar_base</topicName>
            <frameName>base_sonar_01_link</frameName>
            <minRange>0.02</minRange>
            <maxRange>1.0</maxRange>
            <fov>0.5</fov>
            <radiation>ultrasound</radiation>
            <robotNamespace>/</robotNamespace>
          </plugin>
          <pose>-0.183 -0.183 0.2715 0 -0 -2.35619</pose>
        </sensor>
        <sensor name='base_sonar_02' type='ray'>
          <update_rate>5</update_rate>
          <visualize>0</visualize>
          <ray>
            <scan>
              <horizontal>
                <samples>5</samples>
                <resolution>1</resolution>
                <min_angle>-0.25</min_angle>
                <max_angle>0.25</max_angle>
              </horizontal>
              <vertical>
                <samples>5</samples>
                <resolution>1</resolution>
                <min_angle>-0.25</min_angle>
                <max_angle>0.25</max_angle>
              </vertical>
            </scan>
            <range>
              <min>0.02</min>
              <max>1</max>
              <resolution>0.01</resolution>
            </range>
          </ray>
          <plugin name='gazebo_ros_range' filename='libgazebo_ros_range.so'>
            <gaussianNoise>0.005</gaussianNoise>
            <alwaysOn>1</alwaysOn>
            <updateRate>5</updateRate>
            <topicName>sonar_base</topicName>
            <frameName>base_sonar_02_link</frameName>
            <minRange>0.02</minRange>
            <maxRange>1.0</maxRange>
            <fov>0.5</fov>
            <radiation>ultrasound</radiation>
            <robotNamespace>/</robotNamespace>
          </plugin>
          <pose>-0.259 0 0.2715 0 -0 3.14159</pose>
        </sensor>
        <sensor name='base_sonar_03' type='ray'>
          <update_rate>5</update_rate>
          <visualize>0</visualize>
          <ray>
            <scan>
              <horizontal>
                <samples>5</samples>
                <resolution>1</resolution>
                <min_angle>-0.25</min_angle>
                <max_angle>0.25</max_angle>
              </horizontal>
              <vertical>
                <samples>5</samples>
                <resolution>1</resolution>
                <min_angle>-0.25</min_angle>
                <max_angle>0.25</max_angle>
              </vertical>
            </scan>
            <range>
              <min>0.02</min>
              <max>1</max>
              <resolution>0.01</resolution>
            </range>
          </ray>
          <plugin name='gazebo_ros_range' filename='libgazebo_ros_range.so'>
            <gaussianNoise>0.005</gaussianNoise>
            <alwaysOn>1</alwaysOn>
            <updateRate>5</updateRate>
            <topicName>sonar_base</topicName>
            <frameName>base_sonar_03_link</frameName>
            <minRange>0.02</minRange>
            <maxRange>1.0</maxRange>
            <fov>0.5</fov>
            <radiation>ultrasound</radiation>
            <robotNamespace>/</robotNamespace>
          </plugin>
          <pose>-0.183 0.183 0.2715 0 -0 2.35619</pose>
        </sensor>
        <self_collide>0</self_collide>
        <enable_wind>0</enable_wind>
        <kinematic>0</kinematic>
      </link>
      <joint name='caster_back_left_1_joint' type='revolute'>
        <pose relative_to='base_footprint'>-0.1735 0.102 0.065 0 -0 0</pose>
        <parent>base_footprint</parent>
        <child>caster_back_left_1_link</child>
        <axis>
          <xyz>0 0 1</xyz>
          <limit>
            <lower>-1e+16</lower>
            <upper>1e+16</upper>
          </limit>
          <dynamics>
            <damping>0.005</damping>
            <friction>0</friction>
            <spring_reference>0</spring_reference>
            <spring_stiffness>0</spring_stiffness>
          </dynamics>
        </axis>
      </joint>
      <link name='caster_back_left_1_link'>
        <pose relative_to='caster_back_left_1_joint'>0 0 0 0 -0 0</pose>
        <inertial>
          <pose>-0.006346 5.3e-05 -0.020375 0 -0 0</pose>
          <mass>0.0514476</mass>
          <inertia>
            <ixx>1.513e-05</ixx>
            <ixy>-3e-08</ixy>
            <ixz>2.67e-06</ixz>
            <iyy>1.309e-05</iyy>
            <iyz>-5e-08</iyz>
            <izz>1.198e-05</izz>
          </inertia>
        </inertial>
        <visual name='caster_back_left_1_link_visual'>
          <pose>0 0 0 0 -0 0</pose>
          <geometry>
            <mesh>
              <scale>1 1 1</scale>
              <uri>/opt/tiago_public_ws/src/pmb2_robot/pmb2_description/meshes/wheels/caster_1.stl</uri>
            </mesh>
          </geometry>
          <material>
            <script>
              <name>Gazebo/DarkGrey</name>
              <uri>file://media/materials/scripts/gazebo.material</uri>
            </script>
          </material>
        </visual>
        <self_collide>0</self_collide>
        <enable_wind>0</enable_wind>
        <kinematic>0</kinematic>
      </link>
      <joint name='caster_back_left_2_joint' type='revolute'>
        <pose relative_to='caster_back_left_1_link'>-0.016 0 -0.04 -1.5708 0 0</pose>
        <parent>caster_back_left_1_link</parent>
        <child>caster_back_left_2_link</child>
        <axis>
          <xyz>0 0 1</xyz>
          <limit>
            <lower>-1e+16</lower>
            <upper>1e+16</upper>
          </limit>
          <dynamics>
            <spring_reference>0</spring_reference>
            <spring_stiffness>0</spring_stiffness>
          </dynamics>
        </axis>
      </joint>
      <link name='caster_back_left_2_link'>
        <pose relative_to='caster_back_left_2_joint'>0 0 0 0 -0 0</pose>
        <inertial>
          <pose>0 0 0 0 -0 0</pose>
          <mass>0.0885578</mass>
          <inertia>
            <ixx>1.075e-05</ixx>
            <ixy>0</ixy>
            <ixz>0</ixz>
            <iyy>1.541e-05</iyy>
            <iyz>0</iyz>
            <izz>1.075e-05</izz>
          </inertia>
        </inertial>
        <collision name='caster_back_left_2_link_collision'>
          <pose>0 0 0 0 -0 0</pose>
          <geometry>
            <sphere>
              <radius>0.025</radius>
            </sphere>
          </geometry>
          <surface>
            <contact>
              <ode>
                <kp>1e+07</kp>
                <kd>10</kd>
                <max_vel>10</max_vel>
                <min_depth>0.0005</min_depth>
              </ode>
            </contact>
            <friction>
              <ode>
                <mu>0.1</mu>
                <mu2>0.1</mu2>
              </ode>
              <torsional>
                <ode/>
              </torsional>
            </friction>
            <bounce/>
          </surface>
          <max_contacts>10</max_contacts>
        </collision>
        <visual name='caster_back_left_2_link_visual'>
          <pose>0 0 0 0 -0 0</pose>
          <geometry>
            <mesh>
              <scale>1 1 1</scale>
              <uri>/opt/tiago_public_ws/src/pmb2_robot/pmb2_description/meshes/wheels/caster_2.stl</uri>
            </mesh>
          </geometry>
          <material>
            <script>
              <name>Gazebo/DarkGrey</name>
              <uri>file://media/materials/scripts/gazebo.material</uri>
            </script>
          </material>
        </visual>
        <self_collide>0</self_collide>
        <enable_wind>0</enable_wind>
        <kinematic>0</kinematic>
      </link>
      <joint name='caster_back_right_1_joint' type='revolute'>
        <pose relative_to='base_footprint'>-0.1735 -0.102 0.065 0 -0 0</pose>
        <parent>base_footprint</parent>
        <child>caster_back_right_1_link</child>
        <axis>
          <xyz>0 0 1</xyz>
          <limit>
            <lower>-1e+16</lower>
            <upper>1e+16</upper>
          </limit>
          <dynamics>
            <damping>0.005</damping>
            <friction>0</friction>
            <spring_reference>0</spring_reference>
            <spring_stiffness>0</spring_stiffness>
          </dynamics>
        </axis>
      </joint>
      <link name='caster_back_right_1_link'>
        <pose relative_to='caster_back_right_1_joint'>0 0 0 0 -0 0</pose>
        <inertial>
          <pose>-0.006346 5.3e-05 -0.020375 0 -0 0</pose>
          <mass>0.0514476</mass>
          <inertia>
            <ixx>1.513e-05</ixx>
            <ixy>-3e-08</ixy>
            <ixz>2.67e-06</ixz>
            <iyy>1.309e-05</iyy>
            <iyz>-5e-08</iyz>
            <izz>1.198e-05</izz>
          </inertia>
        </inertial>
        <visual name='caster_back_right_1_link_visual'>
          <pose>0 0 0 0 -0 0</pose>
          <geometry>
            <mesh>
              <scale>1 1 1</scale>
              <uri>/opt/tiago_public_ws/src/pmb2_robot/pmb2_description/meshes/wheels/caster_1.stl</uri>
            </mesh>
          </geometry>
          <material>
            <script>
              <name>Gazebo/DarkGrey</name>
              <uri>file://media/materials/scripts/gazebo.material</uri>
            </script>
          </material>
        </visual>
        <self_collide>0</self_collide>
        <enable_wind>0</enable_wind>
        <kinematic>0</kinematic>
      </link>
      <joint name='caster_back_right_2_joint' type='revolute'>
        <pose relative_to='caster_back_right_1_link'>-0.016 0 -0.04 -1.5708 0 0</pose>
        <parent>caster_back_right_1_link</parent>
        <child>caster_back_right_2_link</child>
        <axis>
          <xyz>0 0 1</xyz>
          <limit>
            <lower>-1e+16</lower>
            <upper>1e+16</upper>
          </limit>
          <dynamics>
            <spring_reference>0</spring_reference>
            <spring_stiffness>0</spring_stiffness>
          </dynamics>
        </axis>
      </joint>
      <link name='caster_back_right_2_link'>
        <pose relative_to='caster_back_right_2_joint'>0 0 0 0 -0 0</pose>
        <inertial>
          <pose>0 0 0 0 -0 0</pose>
          <mass>0.0885578</mass>
          <inertia>
            <ixx>1.075e-05</ixx>
            <ixy>0</ixy>
            <ixz>0</ixz>
            <iyy>1.541e-05</iyy>
            <iyz>0</iyz>
            <izz>1.075e-05</izz>
          </inertia>
        </inertial>
        <collision name='caster_back_right_2_link_collision'>
          <pose>0 0 0 0 -0 0</pose>
          <geometry>
            <sphere>
              <radius>0.025</radius>
            </sphere>
          </geometry>
          <surface>
            <contact>
              <ode>
                <kp>1e+07</kp>
                <kd>10</kd>
                <max_vel>10</max_vel>
                <min_depth>0.0005</min_depth>
              </ode>
            </contact>
            <friction>
              <ode>
                <mu>0.1</mu>
                <mu2>0.1</mu2>
              </ode>
              <torsional>
                <ode/>
              </torsional>
            </friction>
            <bounce/>
          </surface>
          <max_contacts>10</max_contacts>
        </collision>
        <visual name='caster_back_right_2_link_visual'>
          <pose>0 0 0 0 -0 0</pose>
          <geometry>
            <mesh>
              <scale>1 1 1</scale>
              <uri>/opt/tiago_public_ws/src/pmb2_robot/pmb2_description/meshes/wheels/caster_2.stl</uri>
            </mesh>
          </geometry>
          <material>
            <script>
              <name>Gazebo/DarkGrey</name>
              <uri>file://media/materials/scripts/gazebo.material</uri>
            </script>
          </material>
        </visual>
        <self_collide>0</self_collide>
        <enable_wind>0</enable_wind>
        <kinematic>0</kinematic>
      </link>
      <joint name='caster_front_left_1_joint' type='revolute'>
        <pose relative_to='base_footprint'>0.1695 0.102 0.065 0 -0 0</pose>
        <parent>base_footprint</parent>
        <child>caster_front_left_1_link</child>
        <axis>
          <xyz>0 0 1</xyz>
          <limit>
            <lower>-1e+16</lower>
            <upper>1e+16</upper>
          </limit>
          <dynamics>
            <damping>0.005</damping>
            <friction>0</friction>
            <spring_reference>0</spring_reference>
            <spring_stiffness>0</spring_stiffness>
          </dynamics>
        </axis>
      </joint>
      <link name='caster_front_left_1_link'>
        <pose relative_to='caster_front_left_1_joint'>0 0 0 0 -0 0</pose>
        <inertial>
          <pose>-0.006346 5.3e-05 -0.020375 0 -0 0</pose>
          <mass>0.0514476</mass>
          <inertia>
            <ixx>1.513e-05</ixx>
            <ixy>-3e-08</ixy>
            <ixz>2.67e-06</ixz>
            <iyy>1.309e-05</iyy>
            <iyz>-5e-08</iyz>
            <izz>1.198e-05</izz>
          </inertia>
        </inertial>
        <visual name='caster_front_left_1_link_visual'>
          <pose>0 0 0 0 -0 0</pose>
          <geometry>
            <mesh>
              <scale>1 1 1</scale>
              <uri>/opt/tiago_public_ws/src/pmb2_robot/pmb2_description/meshes/wheels/caster_1.stl</uri>
            </mesh>
          </geometry>
          <material>
            <script>
              <name>Gazebo/DarkGrey</name>
              <uri>file://media/materials/scripts/gazebo.material</uri>
            </script>
          </material>
        </visual>
        <self_collide>0</self_collide>
        <enable_wind>0</enable_wind>
        <kinematic>0</kinematic>
      </link>
      <joint name='caster_front_left_2_joint' type='revolute'>
        <pose relative_to='caster_front_left_1_link'>-0.016 0 -0.04 -1.5708 0 0</pose>
        <parent>caster_front_left_1_link</parent>
        <child>caster_front_left_2_link</child>
        <axis>
          <xyz>0 0 1</xyz>
          <limit>
            <lower>-1e+16</lower>
            <upper>1e+16</upper>
          </limit>
          <dynamics>
            <spring_reference>0</spring_reference>
            <spring_stiffness>0</spring_stiffness>
          </dynamics>
        </axis>
      </joint>
      <link name='caster_front_left_2_link'>
        <pose relative_to='caster_front_left_2_joint'>0 0 0 0 -0 0</pose>
        <inertial>
          <pose>0 0 0 0 -0 0</pose>
          <mass>0.0885578</mass>
          <inertia>
            <ixx>1.075e-05</ixx>
            <ixy>0</ixy>
            <ixz>0</ixz>
            <iyy>1.541e-05</iyy>
            <iyz>0</iyz>
            <izz>1.075e-05</izz>
          </inertia>
        </inertial>
        <collision name='caster_front_left_2_link_collision'>
          <pose>0 0 0 0 -0 0</pose>
          <geometry>
            <sphere>
              <radius>0.025</radius>
            </sphere>
          </geometry>
          <surface>
            <contact>
              <ode>
                <kp>1e+07</kp>
                <kd>10</kd>
                <max_vel>10</max_vel>
                <min_depth>0.0005</min_depth>
              </ode>
            </contact>
            <friction>
              <ode>
                <mu>0.1</mu>
                <mu2>0.1</mu2>
              </ode>
              <torsional>
                <ode/>
              </torsional>
            </friction>
            <bounce/>
          </surface>
          <max_contacts>10</max_contacts>
        </collision>
        <visual name='caster_front_left_2_link_visual'>
          <pose>0 0 0 0 -0 0</pose>
          <geometry>
            <mesh>
              <scale>1 1 1</scale>
              <uri>/opt/tiago_public_ws/src/pmb2_robot/pmb2_description/meshes/wheels/caster_2.stl</uri>
            </mesh>
          </geometry>
          <material>
            <script>
              <name>Gazebo/DarkGrey</name>
              <uri>file://media/materials/scripts/gazebo.material</uri>
            </script>
          </material>
        </visual>
        <self_collide>0</self_collide>
        <enable_wind>0</enable_wind>
        <kinematic>0</kinematic>
      </link>
      <joint name='caster_front_right_1_joint' type='revolute'>
        <pose relative_to='base_footprint'>0.1695 -0.102 0.065 0 -0 0</pose>
        <parent>base_footprint</parent>
        <child>caster_front_right_1_link</child>
        <axis>
          <xyz>0 0 1</xyz>
          <limit>
            <lower>-1e+16</lower>
            <upper>1e+16</upper>
          </limit>
          <dynamics>
            <damping>0.005</damping>
            <friction>0</friction>
            <spring_reference>0</spring_reference>
            <spring_stiffness>0</spring_stiffness>
          </dynamics>
        </axis>
      </joint>
      <link name='caster_front_right_1_link'>
        <pose relative_to='caster_front_right_1_joint'>0 0 0 0 -0 0</pose>
        <inertial>
          <pose>-0.006346 5.3e-05 -0.020375 0 -0 0</pose>
          <mass>0.0514476</mass>
          <inertia>
            <ixx>1.513e-05</ixx>
            <ixy>-3e-08</ixy>
            <ixz>2.67e-06</ixz>
            <iyy>1.309e-05</iyy>
            <iyz>-5e-08</iyz>
            <izz>1.198e-05</izz>
          </inertia>
        </inertial>
        <visual name='caster_front_right_1_link_visual'>
          <pose>0 0 0 0 -0 0</pose>
          <geometry>
            <mesh>
              <scale>1 1 1</scale>
              <uri>/opt/tiago_public_ws/src/pmb2_robot/pmb2_description/meshes/wheels/caster_1.stl</uri>
            </mesh>
          </geometry>
          <material>
            <script>
              <name>Gazebo/DarkGrey</name>
              <uri>file://media/materials/scripts/gazebo.material</uri>
            </script>
          </material>
        </visual>
        <self_collide>0</self_collide>
        <enable_wind>0</enable_wind>
        <kinematic>0</kinematic>
      </link>
      <joint name='caster_front_right_2_joint' type='revolute'>
        <pose relative_to='caster_front_right_1_link'>-0.016 0 -0.04 -1.5708 0 0</pose>
        <parent>caster_front_right_1_link</parent>
        <child>caster_front_right_2_link</child>
        <axis>
          <xyz>0 0 1</xyz>
          <limit>
            <lower>-1e+16</lower>
            <upper>1e+16</upper>
          </limit>
          <dynamics>
            <spring_reference>0</spring_reference>
            <spring_stiffness>0</spring_stiffness>
          </dynamics>
        </axis>
      </joint>
      <link name='caster_front_right_2_link'>
        <pose relative_to='caster_front_right_2_joint'>0 0 0 0 -0 0</pose>
        <inertial>
          <pose>0 0 0 0 -0 0</pose>
          <mass>0.0885578</mass>
          <inertia>
            <ixx>1.075e-05</ixx>
            <ixy>0</ixy>
            <ixz>0</ixz>
            <iyy>1.541e-05</iyy>
            <iyz>0</iyz>
            <izz>1.075e-05</izz>
          </inertia>
        </inertial>
        <collision name='caster_front_right_2_link_collision'>
          <pose>0 0 0 0 -0 0</pose>
          <geometry>
            <sphere>
              <radius>0.025</radius>
            </sphere>
          </geometry>
          <surface>
            <contact>
              <ode>
                <kp>1e+07</kp>
                <kd>10</kd>
                <max_vel>10</max_vel>
                <min_depth>0.0005</min_depth>
              </ode>
            </contact>
            <friction>
              <ode>
                <mu>0.1</mu>
                <mu2>0.1</mu2>
              </ode>
              <torsional>
                <ode/>
              </torsional>
            </friction>
            <bounce/>
          </surface>
          <max_contacts>10</max_contacts>
        </collision>
        <visual name='caster_front_right_2_link_visual'>
          <pose>0 0 0 0 -0 0</pose>
          <geometry>
            <mesh>
              <scale>1 1 1</scale>
              <uri>/opt/tiago_public_ws/src/pmb2_robot/pmb2_description/meshes/wheels/caster_2.stl</uri>
            </mesh>
          </geometry>
          <material>
            <script>
              <name>Gazebo/DarkGrey</name>
              <uri>file://media/materials/scripts/gazebo.material</uri>
            </script>
          </material>
        </visual>
        <self_collide>0</self_collide>
        <enable_wind>0</enable_wind>
        <kinematic>0</kinematic>
      </link>
      <joint name='suspension_left_joint' type='prismatic'>
        <pose relative_to='base_footprint'>0 0 0.0985 0 -0 0</pose>
        <parent>base_footprint</parent>
        <child>suspension_left_link</child>
        <axis>
          <xyz>0 0 1</xyz>
          <limit>
            <lower>-0.005</lower>
            <upper>0.005</upper>
            <effort>100</effort>
            <velocity>1</velocity>
          </limit>
          <dynamics>
            <damping>100</damping>
            <friction>0</friction>
            <spring_reference>0</spring_reference>
            <spring_stiffness>0</spring_stiffness>
          </dynamics>
        </axis>
      </joint>
      <link name='suspension_left_link'>
        <pose relative_to='suspension_left_joint'>0 0 0 0 -0 0</pose>
        <inertial>
          <pose>0 0 -0.02 0 -0 0</pose>
          <mass>10</mass>
          <inertia>
            <ixx>1</ixx>
            <ixy>0</ixy>
            <ixz>0</ixz>
            <iyy>1</iyy>
            <iyz>0</iyz>
            <izz>1</izz>
          </inertia>
        </inertial>
        <self_collide>0</self_collide>
        <enable_wind>0</enable_wind>
        <kinematic>0</kinematic>
      </link>
      <joint name='wheel_left_joint' type='revolute'>
        <pose relative_to='suspension_left_link'>0 0.2022 0 -1.5708 0 0</pose>
        <parent>suspension_left_link</parent>
        <child>wheel_left_link</child>
        <axis>
          <xyz>0 0 1</xyz>
          <limit>
            <effort>6</effort>
            <velocity>10.1523</velocity>
            <lower>-1e+16</lower>
            <upper>1e+16</upper>
          </limit>
          <dynamics>
            <spring_reference>0</spring_reference>
            <spring_stiffness>0</spring_stiffness>
          </dynamics>
        </axis>
      </joint>
      <link name='wheel_left_link'>
        <pose relative_to='wheel_left_joint'>0 0 0 0 -0 0</pose>
        <inertial>
          <pose>0 0 0.00207 0 -0 0</pose>
          <mass>1.82362</mass>
          <inertia>
            <ixx>0.00499743</ixx>
            <ixy>-4.464e-08</ixy>
            <ixz>-2.245e-08</ixz>
            <iyy>0.00499742</iyy>
            <iyz>1.64e-09</iyz>
            <izz>0.0083924</izz>
          </inertia>
        </inertial>
        <collision name='wheel_left_link_collision'>
          <pose>0 0 0 0 -0 0</pose>
          <geometry>
            <cylinder>
              <length>0.02</length>
              <radius>0.0985</radius>
            </cylinder>
          </geometry>
          <surface>
            <contact>
              <ode>
                <kp>1e+06</kp>
                <kd>100</kd>
                <max_vel>1</max_vel>
                <min_depth>0.002</min_depth>
              </ode>
            </contact>
            <friction>
              <ode>
                <mu>1e+14</mu>
                <mu2>1e+14</mu2>
              </ode>
              <torsional>
                <ode/>
              </torsional>
            </friction>
            <bounce/>
          </surface>
          <max_contacts>10</max_contacts>
        </collision>
        <visual name='wheel_left_link_visual'>
          <pose>0 0 0 -3.14159 0 0</pose>
          <geometry>
            <mesh>
              <scale>1 1 1</scale>
              <uri>/opt/tiago_public_ws/src/pmb2_robot/pmb2_description/meshes/wheels/wheel.stl</uri>
            </mesh>
          </geometry>
          <material>
            <script>
              <name>Gazebo/DarkGrey</name>
              <uri>file://media/materials/scripts/gazebo.material</uri>
            </script>
          </material>
        </visual>
        <self_collide>0</self_collide>
        <enable_wind>0</enable_wind>
        <kinematic>0</kinematic>
      </link>
      <joint name='suspension_right_joint' type='prismatic'>
        <pose relative_to='base_footprint'>0 0 0.0985 0 -0 0</pose>
        <parent>base_footprint</parent>
        <child>suspension_right_link</child>
        <axis>
          <xyz>0 0 1</xyz>
          <limit>
            <lower>-0.005</lower>
            <upper>0.005</upper>
            <effort>100</effort>
            <velocity>1</velocity>
          </limit>
          <dynamics>
            <damping>100</damping>
            <friction>0</friction>
            <spring_reference>0</spring_reference>
            <spring_stiffness>0</spring_stiffness>
          </dynamics>
        </axis>
      </joint>
      <link name='suspension_right_link'>
        <pose relative_to='suspension_right_joint'>0 0 0 0 -0 0</pose>
        <inertial>
          <pose>0 0 -0.02 0 -0 0</pose>
          <mass>10</mass>
          <inertia>
            <ixx>1</ixx>
            <ixy>0</ixy>
            <ixz>0</ixz>
            <iyy>1</iyy>
            <iyz>0</iyz>
            <izz>1</izz>
          </inertia>
        </inertial>
        <self_collide>0</self_collide>
        <enable_wind>0</enable_wind>
        <kinematic>0</kinematic>
      </link>
      <joint name='wheel_right_joint' type='revolute'>
        <pose relative_to='suspension_right_link'>0 -0.2022 0 -1.5708 0 0</pose>
        <parent>suspension_right_link</parent>
        <child>wheel_right_link</child>
        <axis>
          <xyz>0 0 1</xyz>
          <limit>
            <effort>6</effort>
            <velocity>10.1523</velocity>
            <lower>-1e+16</lower>
            <upper>1e+16</upper>
          </limit>
          <dynamics>
            <spring_reference>0</spring_reference>
            <spring_stiffness>0</spring_stiffness>
          </dynamics>
        </axis>
      </joint>
      <link name='wheel_right_link'>
        <pose relative_to='wheel_right_joint'>0 0 0 0 -0 0</pose>
        <inertial>
          <pose>0 0 -0.00207 0 -0 0</pose>
          <mass>1.82362</mass>
          <inertia>
            <ixx>0.00499743</ixx>
            <ixy>4.464e-08</ixy>
            <ixz>-2.245e-08</ixz>
            <iyy>0.00499742</iyy>
            <iyz>-1.64e-09</iyz>
            <izz>0.0083924</izz>
          </inertia>
        </inertial>
        <collision name='wheel_right_link_collision'>
          <pose>0 0 0 0 -0 0</pose>
          <geometry>
            <cylinder>
              <length>0.02</length>
              <radius>0.0985</radius>
            </cylinder>
          </geometry>
          <surface>
            <contact>
              <ode>
                <kp>1e+06</kp>
                <kd>100</kd>
                <max_vel>1</max_vel>
                <min_depth>0.002</min_depth>
              </ode>
            </contact>
            <friction>
              <ode>
                <mu>1e+14</mu>
                <mu2>1e+14</mu2>
              </ode>
              <torsional>
                <ode/>
              </torsional>
            </friction>
            <bounce/>
          </surface>
          <max_contacts>10</max_contacts>
        </collision>
        <visual name='wheel_right_link_visual'>
          <pose>0 0 0 0 -0 0</pose>
          <geometry>
            <mesh>
              <scale>1 1 1</scale>
              <uri>/opt/tiago_public_ws/src/pmb2_robot/pmb2_description/meshes/wheels/wheel.stl</uri>
            </mesh>
          </geometry>
          <material>
            <script>
              <name>Gazebo/DarkGrey</name>
              <uri>file://media/materials/scripts/gazebo.material</uri>
            </script>
          </material>
        </visual>
        <self_collide>0</self_collide>
        <enable_wind>0</enable_wind>
        <kinematic>0</kinematic>
      </link>
      <joint name='torso_lift_joint' type='prismatic'>
        <pose relative_to='base_footprint'>-0.062 0 0.8885 0 -0 0</pose>
        <parent>base_footprint</parent>
        <child>torso_lift_link</child>
        <axis>
          <xyz>0 0 1</xyz>
          <limit>
            <lower>0</lower>
            <upper>0.35</upper>
            <effort>2000</effort>
            <velocity>0.07</velocity>
          </limit>
          <dynamics>
            <damping>1000</damping>
            <friction>0</friction>
            <spring_reference>0</spring_reference>
            <spring_stiffness>0</spring_stiffness>
          </dynamics>
        </axis>
      </joint>
      <link name='torso_lift_link'>
        <pose relative_to='torso_lift_joint'>0 0 0 0 -0 0</pose>
        <inertial>
          <pose>0.04361 -0.00116 -0.17334 0 -0 0</pose>
          <mass>6.93198</mass>
          <inertia>
            <ixx>0.24487</ixx>
            <ixy>-0.001456</ixy>
            <ixz>-0.009742</ixz>
            <iyy>0.249269</iyy>
            <iyz>0.008281</iyz>
            <izz>0.090395</izz>
          </inertia>
        </inertial>
        <collision name='torso_lift_link_collision'>
          <pose>0 0 0 0 -0 0</pose>
          <geometry>
            <mesh>
              <scale>1 1 1</scale>
              <uri>/opt/tiago_public_ws/src/tiago_robot/tiago_description/meshes/torso/torso_lift_collision_core.dae</uri>
            </mesh>
          </geometry>
          <max_contacts>10</max_contacts>
          <surface>
            <contact>
              <ode/>
            </contact>
            <bounce/>
            <friction>
              <torsional>
                <ode/>
              </torsional>
              <ode/>
            </friction>
          </surface>
        </collision>
        <collision name='torso_lift_link_collision_1'>
          <pose>0 0 0 0 -0 0</pose>
          <geometry>
            <mesh>
              <scale>1 1 1</scale>
              <uri>/opt/tiago_public_ws/src/tiago_robot/tiago_description/meshes/torso/torso_lift_collision_shoulder.dae</uri>
            </mesh>
          </geometry>
          <max_contacts>10</max_contacts>
          <surface>
            <contact>
              <ode/>
            </contact>
            <bounce/>
            <friction>
              <torsional>
                <ode/>
              </torsional>
              <ode/>
            </friction>
          </surface>
        </collision>
        <collision name='torso_lift_link_collision_2'>
          <pose>0 0 0 0 -0 0</pose>
          <geometry>
            <mesh>
              <scale>1 1 1</scale>
              <uri>/opt/tiago_public_ws/src/tiago_robot/tiago_description/meshes/torso/torso_lift_collision_neck.dae</uri>
            </mesh>
          </geometry>
          <max_contacts>10</max_contacts>
          <surface>
            <contact>
              <ode/>
            </contact>
            <bounce/>
            <friction>
              <torsional>
                <ode/>
              </torsional>
              <ode/>
            </friction>
          </surface>
        </collision>
        <visual name='torso_lift_link_visual'>
          <pose>0 0 0 0 -0 0</pose>
          <geometry>
            <mesh>
              <scale>1 1 1</scale>
              <uri>/opt/tiago_public_ws/src/tiago_robot/tiago_description/meshes/torso/torso_lift_with_arm.stl</uri>
            </mesh>
          </geometry>
        </visual>
        <self_collide>0</self_collide>
        <enable_wind>0</enable_wind>
        <kinematic>0</kinematic>
      </link>
      <joint name='arm_1_joint' type='revolute'>
        <pose relative_to='torso_lift_link'>0.15505 0.014 -0.151 0 0 -1.5708</pose>
        <parent>torso_lift_link</parent>
        <child>arm_1_link</child>
        <axis>
          <xyz>0 0 1</xyz>
          <limit>
            <lower>0</lower>
            <upper>2.74889</upper>
            <effort>43</effort>
            <velocity>1.95</velocity>
          </limit>
          <dynamics>
            <damping>1</damping>
            <friction>1</friction>
            <spring_reference>0</spring_reference>
            <spring_stiffness>0</spring_stiffness>
          </dynamics>
        </axis>
        <physics>
          <ode>
            <implicit_spring_damper>1</implicit_spring_damper>
            <cfm_damping>1</cfm_damping>
            <limit>
              <cfm>0</cfm>
              <erp>0.2</erp>
            </limit>
          </ode>
        </physics>
      </joint>
      <link name='arm_1_link'>
        <pose relative_to='arm_1_joint'>0 0 0 0 -0 0</pose>
        <inertial>
          <pose>0.061191 -0.022397 -0.012835 0 -0 0</pose>
          <mass>1.56343</mass>
          <inertia>
            <ixx>0.002471</ixx>
            <ixy>-0.001809</ixy>
            <ixz>-0.001202</ixz>
            <iyy>0.006132</iyy>
            <iyz>0.000494</iyz>
            <izz>0.006704</izz>
          </inertia>
        </inertial>
        <collision name='arm_1_link_collision'>
          <pose>0 0 0 0 -0 0</pose>
          <geometry>
            <mesh>
              <scale>1 1 1</scale>
              <uri>/opt/tiago_public_ws/src/tiago_robot/tiago_description/meshes/arm/arm_1_collision.dae</uri>
            </mesh>
          </geometry>
          <surface>
            <contact>
              <ode/>
            </contact>
            <friction>
              <ode>
                <mu>0.9</mu>
                <mu2>0.9</mu2>
              </ode>
              <torsional>
                <ode/>
              </torsional>
            </friction>
            <bounce/>
          </surface>
          <max_contacts>10</max_contacts>
        </collision>
        <visual name='arm_1_link_visual'>
          <pose>0 0 0 0 -0 0</pose>
          <geometry>
            <mesh>
              <scale>1 1 1</scale>
              <uri>/opt/tiago_public_ws/src/tiago_robot/tiago_description/meshes/arm/arm_1.stl</uri>
            </mesh>
          </geometry>
          <material>
            <script>
              <name>Gazebo/DarkGrey</name>
              <uri>file://media/materials/scripts/gazebo.material</uri>
            </script>
          </material>
        </visual>
        <self_collide>0</self_collide>
        <enable_wind>0</enable_wind>
        <kinematic>0</kinematic>
      </link>
      <joint name='arm_2_joint' type='revolute'>
        <pose relative_to='arm_1_link'>0.125 0.0195 -0.031 1.5708 -0 0</pose>
        <parent>arm_1_link</parent>
        <child>arm_2_link</child>
        <axis>
          <xyz>0 0 1</xyz>
          <limit>
            <lower>-1.5708</lower>
            <upper>1.09083</upper>
            <effort>43</effort>
            <velocity>1.95</velocity>
          </limit>
          <dynamics>
            <damping>1</damping>
            <friction>1</friction>
            <spring_reference>0</spring_reference>
            <spring_stiffness>0</spring_stiffness>
          </dynamics>
        </axis>
        <physics>
          <ode>
            <implicit_spring_damper>1</implicit_spring_damper>
            <cfm_damping>1</cfm_damping>
            <limit>
              <cfm>0</cfm>
              <erp>0.2</erp>
            </limit>
          </ode>
        </physics>
      </joint>
      <link name='arm_2_link'>
        <pose relative_to='arm_2_joint'>0 0 0 0 -0 0</pose>
        <inertial>
          <pose>0.030432 0.000229 -0.005942 0 -0 0</pose>
          <mass>1.8004</mass>
          <inertia>
            <ixx>0.001809</ixx>
            <ixy>1.5e-05</ixy>
            <ixz>0.000254</ixz>
            <iyy>0.004333</iyy>
            <iyz>1.4e-05</iyz>
            <izz>0.004341</izz>
          </inertia>
        </inertial>
        <collision name='arm_2_link_collision'>
          <pose>0 0 0 0 -0 0</pose>
          <geometry>
            <mesh>
              <scale>1 1 1</scale>
              <uri>/opt/tiago_public_ws/src/tiago_robot/tiago_description/meshes/arm/arm_2_collision.dae</uri>
            </mesh>
          </geometry>
          <surface>
            <contact>
              <ode/>
            </contact>
            <friction>
              <ode>
                <mu>0.9</mu>
                <mu2>0.9</mu2>
              </ode>
              <torsional>
                <ode/>
              </torsional>
            </friction>
            <bounce/>
          </surface>
          <max_contacts>10</max_contacts>
        </collision>
        <visual name='arm_2_link_visual'>
          <pose>0 0 0 0 -0 0</pose>
          <geometry>
            <mesh>
              <scale>1 1 1</scale>
              <uri>/opt/tiago_public_ws/src/tiago_robot/tiago_description/meshes/arm/arm_2.stl</uri>
            </mesh>
          </geometry>
          <material>
            <script>
              <name>Gazebo/DarkGrey</name>
              <uri>file://media/materials/scripts/gazebo.material</uri>
            </script>
          </material>
        </visual>
        <self_collide>0</self_collide>
        <enable_wind>0</enable_wind>
        <kinematic>0</kinematic>
      </link>
      <joint name='arm_3_joint' type='revolute'>
        <pose relative_to='arm_2_link'>0.0895 0 -0.0015 -1.5708 0 1.5708</pose>
        <parent>arm_2_link</parent>
        <child>arm_3_link</child>
        <axis>
          <xyz>0 0 1</xyz>
          <limit>
            <lower>-3.53429</lower>
            <upper>1.5708</upper>
            <effort>26</effort>
            <velocity>2.35</velocity>
          </limit>
          <dynamics>
            <damping>1</damping>
            <friction>1</friction>
            <spring_reference>0</spring_reference>
            <spring_stiffness>0</spring_stiffness>
          </dynamics>
        </axis>
        <physics>
          <ode>
            <implicit_spring_damper>1</implicit_spring_damper>
            <cfm_damping>1</cfm_damping>
            <limit>
              <cfm>0</cfm>
              <erp>0.2</erp>
            </limit>
          </ode>
        </physics>
      </joint>
      <link name='arm_3_link'>
        <pose relative_to='arm_3_joint'>0 0 0 0 -0 0</pose>
        <inertial>
          <pose>0.007418 -0.004361 -0.134194 0 -0 0</pose>
          <mass>1.8</mass>
          <inertia>
            <ixx>0.019541</ixx>
            <ixy>-0.000105</ixy>
            <ixz>-0.001717</ixz>
            <iyy>0.019936</iyy>
            <iyz>0.000852</iyz>
            <izz>0.002864</izz>
          </inertia>
        </inertial>
        <collision name='arm_3_link_collision'>
          <pose>0 0 0 0 -0 0</pose>
          <geometry>
            <mesh>
              <scale>1 1 1</scale>
              <uri>/opt/tiago_public_ws/src/tiago_robot/tiago_description/meshes/arm/arm_3_collision.dae</uri>
            </mesh>
          </geometry>
          <surface>
            <contact>
              <ode/>
            </contact>
            <friction>
              <ode>
                <mu>0.9</mu>
                <mu2>0.9</mu2>
              </ode>
              <torsional>
                <ode/>
              </torsional>
            </friction>
            <bounce/>
          </surface>
          <max_contacts>10</max_contacts>
        </collision>
        <visual name='arm_3_link_visual'>
          <pose>0 0 0 0 -0 0</pose>
          <geometry>
            <mesh>
              <scale>1 1 1</scale>
              <uri>/opt/tiago_public_ws/src/tiago_robot/tiago_description/meshes/arm/arm_3.stl</uri>
            </mesh>
          </geometry>
          <material>
            <script>
              <name>Gazebo/DarkGrey</name>
              <uri>file://media/materials/scripts/gazebo.material</uri>
            </script>
          </material>
        </visual>
        <self_collide>0</self_collide>
        <enable_wind>0</enable_wind>
        <kinematic>0</kinematic>
      </link>
      <joint name='arm_4_joint' type='revolute'>
        <pose relative_to='arm_3_link'>-0.02 -0.027 -0.222 1.57079 -1.57079 3.14159</pose>
        <parent>arm_3_link</parent>
        <child>arm_4_link</child>
        <axis>
          <xyz>0 0 1</xyz>
          <limit>
            <lower>-0.392699</lower>
            <upper>2.35619</upper>
            <effort>26</effort>
            <velocity>2.35</velocity>
          </limit>
          <dynamics>
            <damping>1</damping>
            <friction>1</friction>
            <spring_reference>0</spring_reference>
            <spring_stiffness>0</spring_stiffness>
          </dynamics>
        </axis>
        <physics>
          <ode>
            <implicit_spring_damper>1</implicit_spring_damper>
            <cfm_damping>1</cfm_damping>
            <limit>
              <cfm>0</cfm>
              <erp>0.2</erp>
            </limit>
          </ode>
        </physics>
      </joint>
      <link name='arm_4_link'>
        <pose relative_to='arm_4_joint'>0 0 0 0 -0 0</pose>
        <inertial>
          <pose>-0.095658 0.014666 0.018133 0 -0 0</pose>
          <mass>1.4327</mass>
          <inertia>
            <ixx>0.00204</ixx>
            <ixy>0.000725</ixy>
            <ixz>-0.00115</ixz>
            <iyy>0.008424</iyy>
            <iyz>-0.000204</iyz>
            <izz>0.008686</izz>
          </inertia>
        </inertial>
        <collision name='arm_4_link_collision'>
          <pose>0 0 0 0 -0 0</pose>
          <geometry>
            <mesh>
              <scale>1 1 1</scale>
              <uri>/opt/tiago_public_ws/src/tiago_robot/tiago_description/meshes/arm/arm_4_collision.dae</uri>
            </mesh>
          </geometry>
          <surface>
            <contact>
              <ode/>
            </contact>
            <friction>
              <ode>
                <mu>0.9</mu>
                <mu2>0.9</mu2>
              </ode>
              <torsional>
                <ode/>
              </torsional>
            </friction>
            <bounce/>
          </surface>
          <max_contacts>10</max_contacts>
        </collision>
        <visual name='arm_4_link_visual'>
          <pose>0 0 0 0 -0 0</pose>
          <geometry>
            <mesh>
              <scale>1 1 1</scale>
              <uri>/opt/tiago_public_ws/src/tiago_robot/tiago_description/meshes/arm/arm_4.stl</uri>
            </mesh>
          </geometry>
          <material>
            <script>
              <name>Gazebo/DarkGrey</name>
              <uri>file://media/materials/scripts/gazebo.material</uri>
            </script>
          </material>
        </visual>
        <self_collide>0</self_collide>
        <enable_wind>0</enable_wind>
        <kinematic>0</kinematic>
      </link>
      <joint name='arm_5_joint' type='revolute'>
        <pose relative_to='arm_4_link'>-0.162 0.02 0.027 3.14159 -1.57079 3.14159</pose>
        <parent>arm_4_link</parent>
        <child>arm_5_link</child>
        <axis>
          <xyz>0 0 1</xyz>
          <limit>
            <lower>-2.0944</lower>
            <upper>2.0944</upper>
            <effort>3</effort>
            <velocity>1.95</velocity>
          </limit>
          <dynamics>
            <damping>1</damping>
            <friction>1</friction>
            <spring_reference>0</spring_reference>
            <spring_stiffness>0</spring_stiffness>
          </dynamics>
        </axis>
        <physics>
          <ode>
            <implicit_spring_damper>1</implicit_spring_damper>
            <cfm_damping>1</cfm_damping>
            <limit>
              <cfm>0</cfm>
              <erp>0.2</erp>
            </limit>
          </ode>
        </physics>
      </joint>
      <link name='arm_5_link'>
        <pose relative_to='arm_5_joint'>0 0 0 0 -0 0</pose>
        <inertial>
          <pose>0.001078 -0.000151 -0.077173 0 -0 0</pose>
          <mass>0.935914</mass>
          <inertia>
            <ixx>0.00103619</ixx>
            <ixy>1.06223e-07</ixy>
            <ixz>1.99203e-06</ixz>
            <iyy>0.000794527</iyy>
            <iyz>-2.56396e-07</iyz>
            <izz>0.000439831</izz>
          </inertia>
        </inertial>
        <collision name='arm_5_link_collision'>
          <pose>0 0 0 0 -0 0</pose>
          <geometry>
            <mesh>
              <scale>1 1 1</scale>
              <uri>/opt/tiago_public_ws/src/tiago_robot/tiago_description/meshes/arm/arm_5_collision-wrist-2017.dae</uri>
            </mesh>
          </geometry>
          <surface>
            <contact>
              <ode/>
            </contact>
            <friction>
              <ode>
                <mu>0.9</mu>
                <mu2>0.9</mu2>
              </ode>
              <torsional>
                <ode/>
              </torsional>
            </friction>
            <bounce/>
          </surface>
          <max_contacts>10</max_contacts>
        </collision>
        <visual name='arm_5_link_visual'>
          <pose>0 0 0 0 -0 0</pose>
          <geometry>
            <mesh>
              <scale>1 1 1</scale>
              <uri>/opt/tiago_public_ws/src/tiago_robot/tiago_description/meshes/arm/arm_5-wrist-2017.stl</uri>
            </mesh>
          </geometry>
        </visual>
        <self_collide>0</self_collide>
        <enable_wind>0</enable_wind>
        <kinematic>0</kinematic>
      </link>
      <joint name='arm_6_joint' type='revolute'>
        <pose relative_to='arm_5_link'>0 0 0.15 1.57079 -1.57079 3.14159</pose>
        <parent>arm_5_link</parent>
        <child>arm_6_link</child>
        <axis>
          <xyz>0 0 1</xyz>
          <limit>
            <lower>-1.41372</lower>
            <upper>1.41372</upper>
            <effort>6.6</effort>
            <velocity>1.76</velocity>
          </limit>
          <dynamics>
            <damping>1</damping>
            <friction>1</friction>
            <spring_reference>0</spring_reference>
            <spring_stiffness>0</spring_stiffness>
          </dynamics>
        </axis>
        <physics>
          <ode>
            <implicit_spring_damper>1</implicit_spring_damper>
            <cfm_damping>1</cfm_damping>
            <limit>
              <cfm>0</cfm>
              <erp>0.2</erp>
            </limit>
          </ode>
        </physics>
      </joint>
      <link name='arm_6_link'>
        <pose relative_to='arm_6_joint'>0 0 0 0 -0 0</pose>
        <inertial>
          <pose>-0.000153 -0.003122 0.000183 0 -0 0</pose>
          <mass>0.302758</mass>
          <inertia>
            <ixx>3.29234e-05</ixx>
            <ixy>6.31537e-08</ixy>
            <ixz>-4.56712e-11</ixz>
            <iyy>3.85334e-05</iyy>
            <iyz>-2.01613e-07</iyz>
            <izz>3.33283e-05</izz>
          </inertia>
        </inertial>
        <collision name='arm_6_link_collision'>
          <pose>0 0 0 0 -0 0</pose>
          <geometry>
            <mesh>
              <scale>1 1 1</scale>
              <uri>/opt/tiago_public_ws/src/tiago_robot/tiago_description/meshes/arm/arm_6_collision-wrist-2017.dae</uri>
            </mesh>
          </geometry>
          <surface>
            <contact>
              <ode/>
            </contact>
            <friction>
              <ode>
                <mu>0.9</mu>
                <mu2>0.9</mu2>
              </ode>
              <torsional>
                <ode/>
              </torsional>
            </friction>
            <bounce/>
          </surface>
          <max_contacts>10</max_contacts>
        </collision>
        <visual name='arm_6_link_visual'>
          <pose>0 0 0 0 -0 0</pose>
          <geometry>
            <mesh>
              <scale>1 1 1</scale>
              <uri>/opt/tiago_public_ws/src/tiago_robot/tiago_description/meshes/arm/arm_6-wrist-2017.stl</uri>
            </mesh>
          </geometry>
        </visual>
        <self_collide>0</self_collide>
        <enable_wind>0</enable_wind>
        <kinematic>0</kinematic>
      </link>
      <joint name='arm_7_joint' type='revolute'>
        <pose relative_to='arm_6_link'>0 0 0 1.5708 -0 1.5708</pose>
        <parent>arm_6_link</parent>
        <child>arm_7_link</child>
        <axis>
          <xyz>0 0 1</xyz>
          <limit>
            <lower>-2.0944</lower>
            <upper>2.0944</upper>
            <effort>6.6</effort>
            <velocity>1.76</velocity>
          </limit>
          <dynamics>
            <damping>1</damping>
            <friction>1</friction>
            <spring_reference>0</spring_reference>
            <spring_stiffness>0</spring_stiffness>
          </dynamics>
        </axis>
        <physics>
          <provide_feedback>1</provide_feedback>
          <ode>
            <implicit_spring_damper>1</implicit_spring_damper>
            <cfm_damping>1</cfm_damping>
            <limit>
              <cfm>0</cfm>
              <erp>0.2</erp>
            </limit>
            <provide_feedback>1</provide_feedback>
          </ode>
        </physics>
      </joint>
      <link name='arm_7_link'>
        <pose relative_to='arm_7_joint'>0 0 0 0 -0 0</pose>
        <inertial>
          <pose>-0.000217 0.00022 0.081541 0 -0 0</pose>
          <mass>0.80276</mass>
          <inertia>
            <ixx>0.00211687</ixx>
            <ixy>4.48741e-05</ixy>
            <ixz>3.40015e-06</ixz>
            <iyy>0.00178615</iyy>
            <iyz>-3.38361e-06</iyz>
            <izz>0.000703049</izz>
          </inertia>
        </inertial>
        <collision name='arm_7_link_fixed_joint_lump__arm_tool_link_collision'>
          <pose>-0 0 0.0583 0 -0 -1.5708</pose>
          <geometry>
            <cylinder>
              <length>0.005</length>
              <radius>0.005</radius>
            </cylinder>
          </geometry>
          <max_contacts>10</max_contacts>
          <surface>
            <contact>
              <ode/>
            </contact>
            <bounce/>
            <friction>
              <torsional>
                <ode/>
              </torsional>
              <ode/>
            </friction>
          </surface>
        </collision>
        <collision name='arm_7_link_fixed_joint_lump__gripper_link_collision_1'>
          <pose>-0 -0 0.0673 3.14159 -0 -1.5708</pose>
          <geometry>
            <mesh>
              <scale>1 1 1</scale>
              <uri>/opt/tiago_public_ws/src/pal_gripper/pal_gripper_description/meshes/gripper_link_collision.stl</uri>
            </mesh>
          </geometry>
          <surface>
            <contact>
              <ode/>
            </contact>
            <friction>
              <ode/>
              <torsional>
                <ode/>
              </torsional>
            </friction>
            <bounce/>
          </surface>
          <max_contacts>10</max_contacts>
        </collision>
        <visual name='arm_7_link_fixed_joint_lump__arm_tool_link_visual'>
          <pose>-0 0 0.0583 0 -0 -1.5708</pose>
          <geometry>
            <cylinder>
              <length>0.005</length>
              <radius>0.005</radius>
            </cylinder>
          </geometry>
        </visual>
        <visual name='arm_7_link_fixed_joint_lump__gripper_link_visual_1'>
          <pose>-0 -0 0.0673 3.14159 -0 -1.5708</pose>
          <geometry>
            <mesh>
              <scale>1 1 1</scale>
              <uri>/opt/tiago_public_ws/src/pal_gripper/pal_gripper_description/meshes/gripper_link.stl</uri>
            </mesh>
          </geometry>
          <material>
            <script>
              <name>Gazebo/White</name>
              <uri>file://media/materials/scripts/gazebo.material</uri>
            </script>
          </material>
        </visual>
        <self_collide>0</self_collide>
        <enable_wind>0</enable_wind>
        <kinematic>0</kinematic>
      </link>
      <joint name='gripper_left_finger_joint' type='prismatic'>
        <pose relative_to='arm_7_link'>-0 -0 0.0673 3.14159 -0 -1.5708</pose>
        <parent>arm_7_link</parent>
        <child>gripper_left_finger_link</child>
        <axis>
          <xyz>-1 0 0</xyz>
          <limit>
            <lower>0</lower>
            <upper>0.045</upper>
            <effort>64</effort>
            <velocity>0.05</velocity>
          </limit>
          <dynamics>
            <damping>1</damping>
            <friction>0</friction>
            <spring_reference>0</spring_reference>
            <spring_stiffness>0</spring_stiffness>
          </dynamics>
        </axis>
        <physics>
          <provide_feedback>1</provide_feedback>
          <ode>
            <implicit_spring_damper>1</implicit_spring_damper>
            <cfm_damping>1</cfm_damping>
            <limit>
              <cfm>0</cfm>
              <erp>0.2</erp>
            </limit>
            <provide_feedback>1</provide_feedback>
          </ode>
        </physics>
      </joint>
      <link name='gripper_left_finger_link'>
        <pose relative_to='gripper_left_finger_joint'>0 0 0 0 -0 0</pose>
        <inertial>
          <pose>-0.00447 0.010766 -0.121013 0 -0 0</pose>
          <mass>0.10998</mass>
          <inertia>
            <ixx>0.000232</ixx>
            <ixy>-5e-06</ixy>
            <ixz>-3.2e-05</ixz>
            <iyy>0.000224</iyy>
            <iyz>3.6e-05</iyz>
            <izz>2.9e-05</izz>
          </inertia>
        </inertial>
        <collision name='gripper_left_finger_link_collision'>
          <pose>-0.005 0 -0.165 0 -0 3.1415</pose>
          <geometry>
            <box>
              <size>0.01 0.05 0.11</size>
            </box>
          </geometry>
          <surface>
            <friction>
              <torsional>
                <coefficient>1000</coefficient>
                <use_patch_radius>1</use_patch_radius>
                <patch_radius>0.1</patch_radius>
                <ode/>
              </torsional>
              <ode>
                <mu>inf</mu>
                <mu2>inf</mu2>
                <fdir1>1 0 0</fdir1>
              </ode>
            </friction>
            <contact>
              <poissons_ratio>1</poissons_ratio>
              <elastic_modulus>inf</elastic_modulus>
              <ode>
                <kp>inf</kp>
                <kd>100</kd>
                <max_vel>0</max_vel>
                <min_depth>0.002</min_depth>
              </ode>
            </contact>
            <bounce/>
          </surface>
          <max_contacts>100</max_contacts>
        </collision>
        <visual name='gripper_left_finger_link_visual'>
          <pose>0 0 0 0 -0 3.1415</pose>
          <geometry>
            <mesh>
              <scale>1 1 1</scale>
              <uri>/opt/tiago_public_ws/src/pal_gripper/pal_gripper_description/meshes/gripper_finger_link.stl</uri>
            </mesh>
          </geometry>
          <material>
            <script>
              <name>Gazebo/Black</name>
              <uri>file://media/materials/scripts/gazebo.material</uri>
            </script>
          </material>
        </visual>
        <self_collide>0</self_collide>
        <enable_wind>0</enable_wind>
        <kinematic>0</kinematic>
      </link>
      <joint name='gripper_right_finger_joint' type='prismatic'>
        <pose relative_to='arm_7_link'>-0 -0 0.0673 3.14159 -0 -1.5708</pose>
        <parent>arm_7_link</parent>
        <child>gripper_right_finger_link</child>
        <axis>
          <xyz>1 0 0</xyz>
          <limit>
            <lower>0</lower>
            <upper>0.045</upper>
            <effort>64</effort>
            <velocity>0.05</velocity>
          </limit>
          <dynamics>
            <damping>1</damping>
            <friction>0</friction>
            <spring_reference>0</spring_reference>
            <spring_stiffness>0</spring_stiffness>
          </dynamics>
        </axis>
        <physics>
          <provide_feedback>1</provide_feedback>
          <ode>
            <implicit_spring_damper>1</implicit_spring_damper>
            <cfm_damping>1</cfm_damping>
            <limit>
              <cfm>0</cfm>
              <erp>0.2</erp>
            </limit>
            <provide_feedback>1</provide_feedback>
          </ode>
        </physics>
      </joint>
      <link name='gripper_right_finger_link'>
        <pose relative_to='gripper_right_finger_joint'>0 0 0 0 -0 0</pose>
        <inertial>
          <pose>-0.00447 0.010766 -0.121013 0 -0 0</pose>
          <mass>0.10998</mass>
          <inertia>
            <ixx>0.000232</ixx>
            <ixy>-5e-06</ixy>
            <ixz>-3.2e-05</ixz>
            <iyy>0.000224</iyy>
            <iyz>3.6e-05</iyz>
            <izz>2.9e-05</izz>
          </inertia>
        </inertial>
        <collision name='gripper_right_finger_link_collision'>
          <pose>0.005 0 -0.165 0 -0 3.1415</pose>
          <geometry>
            <box>
              <size>0.01 0.05 0.11</size>
            </box>
          </geometry>
          <surface>
            <friction>
              <torsional>
                <coefficient>1000</coefficient>
                <use_patch_radius>1</use_patch_radius>
                <patch_radius>0.1</patch_radius>
                <ode/>
              </torsional>
              <ode>
                <mu>inf</mu>
                <mu2>inf</mu2>
                <fdir1>1 0 0</fdir1>
              </ode>
            </friction>
            <contact>
              <poissons_ratio>1</poissons_ratio>
              <elastic_modulus>inf</elastic_modulus>
              <ode>
                <kp>inf</kp>
                <kd>100</kd>
                <max_vel>0</max_vel>
                <min_depth>0.002</min_depth>
              </ode>
            </contact>
            <bounce/>
          </surface>
          <max_contacts>100</max_contacts>
        </collision>
        <visual name='gripper_right_finger_link_visual'>
          <pose>0 0 0 0 -0 3.1415</pose>
          <geometry>
            <mesh>
              <scale>-1 -1 1</scale>
              <uri>/opt/tiago_public_ws/src/pal_gripper/pal_gripper_description/meshes/gripper_finger_link.stl</uri>
            </mesh>
          </geometry>
          <material>
            <script>
              <name>Gazebo/Black</name>
              <uri>file://media/materials/scripts/gazebo.material</uri>
            </script>
          </material>
        </visual>
        <self_collide>0</self_collide>
        <enable_wind>0</enable_wind>
        <kinematic>0</kinematic>
      </link>
      <joint name='head_1_joint' type='revolute'>
        <pose relative_to='torso_lift_link'>0.182 0 0 0 -0 0</pose>
        <parent>torso_lift_link</parent>
        <child>head_1_link</child>
        <axis>
          <xyz>0 0 1</xyz>
          <limit>
            <lower>-1.309</lower>
            <upper>1.309</upper>
            <effort>5.197</effort>
            <velocity>3</velocity>
          </limit>
          <dynamics>
            <damping>0.5</damping>
            <friction>1</friction>
            <spring_reference>0</spring_reference>
            <spring_stiffness>0</spring_stiffness>
          </dynamics>
        </axis>
        <physics>
          <ode>
            <implicit_spring_damper>1</implicit_spring_damper>
            <cfm_damping>1</cfm_damping>
            <limit>
              <cfm>0</cfm>
              <erp>0.2</erp>
            </limit>
          </ode>
        </physics>
      </joint>
      <link name='head_1_link'>
        <pose relative_to='head_1_joint'>0 0 0 0 -0 0</pose>
        <inertial>
          <pose>-0.00508 0.00237 0.07229 0 -0 0</pose>
          <mass>0.6222</mass>
          <inertia>
            <ixx>0.001192</ixx>
            <ixy>-7e-06</ixy>
            <ixz>9.6e-05</ixz>
            <iyy>0.001402</iyy>
            <iyz>4e-06</iyz>
            <izz>0.000889</izz>
          </inertia>
        </inertial>
        <collision name='head_1_link_collision'>
          <pose>0 0 0 0 -0 0</pose>
          <geometry>
            <mesh>
              <scale>1 1 1</scale>
              <uri>/opt/tiago_public_ws/src/tiago_robot/tiago_description/meshes/head/head_1_collision.dae</uri>
            </mesh>
          </geometry>
          <surface>
            <contact>
              <ode/>
            </contact>
            <friction>
              <ode>
                <mu>0.9</mu>
                <mu2>0.9</mu2>
              </ode>
              <torsional>
                <ode/>
              </torsional>
            </friction>
            <bounce/>
          </surface>
          <max_contacts>10</max_contacts>
        </collision>
        <visual name='head_1_link_visual'>
          <pose>0 0 0 0 -0 0</pose>
          <geometry>
            <mesh>
              <scale>1 1 1</scale>
              <uri>/opt/tiago_public_ws/src/tiago_robot/tiago_description/meshes/head/head_1.stl</uri>
            </mesh>
          </geometry>
        </visual>
        <self_collide>0</self_collide>
        <enable_wind>0</enable_wind>
        <kinematic>0</kinematic>
      </link>
      <joint name='head_2_joint' type='revolute'>
        <pose relative_to='head_1_link'>0.005 0 0.098 1.5708 -0 0</pose>
        <parent>head_1_link</parent>
        <child>head_2_link</child>
        <axis>
          <xyz>0 0 1</xyz>
          <limit>
            <lower>-1.0472</lower>
            <upper>0.785398</upper>
            <effort>2.77</effort>
            <velocity>3</velocity>
          </limit>
          <dynamics>
            <damping>0.5</damping>
            <friction>1</friction>
            <spring_reference>0</spring_reference>
            <spring_stiffness>0</spring_stiffness>
          </dynamics>
        </axis>
      </joint>
      <link name='head_2_link'>
        <pose relative_to='head_2_joint'>0 0 0 0 -0 0</pose>
        <inertial>
          <pose>0.055827 0.060999 1.6e-05 0 -0 0</pose>
          <mass>0.88693</mass>
          <inertia>
            <ixx>0.00477062</ixx>
            <ixy>0.000560916</ixy>
            <ixz>1.19415e-05</ixz>
            <iyy>0.00513368</iyy>
            <iyz>9.32647e-06</iyz>
            <izz>0.00347598</izz>
          </inertia>
        </inertial>
        <collision name='head_2_link_collision'>
          <pose>0 0 0 0 -0 0</pose>
          <geometry>
            <mesh>
              <scale>1 1 1</scale>
              <uri>/opt/tiago_public_ws/src/tiago_robot/tiago_description/meshes/head/head_2_collision.dae</uri>
            </mesh>
          </geometry>
          <max_contacts>10</max_contacts>
          <surface>
            <contact>
              <ode/>
            </contact>
            <bounce/>
            <friction>
              <torsional>
                <ode/>
              </torsional>
              <ode/>
            </friction>
          </surface>
        </collision>
        <visual name='head_2_link_visual'>
          <pose>0 0 0 0 -0 0</pose>
          <geometry>
            <mesh>
              <scale>1 1 1</scale>
              <uri>/opt/tiago_public_ws/src/tiago_robot/tiago_description/meshes/head/head_2.stl</uri>
            </mesh>
          </geometry>
        </visual>
        <sensor name='xtion_frame_sensor' type='depth'>
          <always_on>1</always_on>
          <update_rate>30</update_rate>
          <camera>
            <horizontal_fov>1.09956</horizontal_fov>
            <image>
              <format>B8G8R8</format>
              <width>640</width>
              <height>480</height>
            </image>
            <clip>
              <near>0.3</near>
              <far>8</far>
            </clip>
          </camera>
          <plugin name='xtion_frame_controller' filename='libgazebo_ros_openni_kinect.so'>
            <alwaysOn>1</alwaysOn>
            <updateRate>30.0</updateRate>
            <cameraName>xtion</cameraName>
            <imageTopicName>rgb/image_raw</imageTopicName>
            <cameraInfoTopicName>rgb/camera_info</cameraInfoTopicName>
            <depthImageTopicName>depth_registered/image_raw</depthImageTopicName>
            <depthImageCameraInfoTopicName>depth_registered/camera_info</depthImageCameraInfoTopicName>
            <pointCloudTopicName>depth_registered/points</pointCloudTopicName>
            <frameName>xtion_rgb_optical_frame</frameName>
            <pointCloudCutoff>0.5</pointCloudCutoff>
            <pointCloudCutoffMax>8.0</pointCloudCutoffMax>
            <distortionK1>0.00000001</distortionK1>
            <distortionK2>0.00000001</distortionK2>
            <distortionK3>0.00000001</distortionK3>
            <distortionT1>0.00000001</distortionT1>
            <distortionT2>0.00000001</distortionT2>
            <robotNamespace>/</robotNamespace>
          </plugin>
          <pose>0.0908 0.08 -0.022 -1.5708 0 0</pose>
        </sensor>
        <self_collide>0</self_collide>
        <enable_wind>0</enable_wind>
        <kinematic>0</kinematic>
      </link>
      <plugin name='gazebo_ros_control' filename='libgazebo_ros_control.so'>
        <ns/>
        <robotSimType>pal_hardware_gazebo/PalHardwareGazebo</robotSimType>
        <robotNamespace/>
        <controlPeriod>0.01</controlPeriod>
      </plugin>
      <plugin name='gazebo_ros_p3d' filename='libgazebo_ros_p3d.so'>
        <bodyName>base_footprint</bodyName>
        <topicName>ground_truth_odom</topicName>
        <alwaysOn>1</alwaysOn>
        <updateRate>100.0</updateRate>
        <robotNamespace>/</robotNamespace>
      </plugin>
      <plugin name='gazebo_ros_odometry' filename='libgazebo_world_odometry.so'>
        <frameName>base_footprint</frameName>
        <topicName>floating_base_pose_simulated</topicName>
        <robotNamespace>/</robotNamespace>
      </plugin>
      <static>0</static>
      <gripper name='gripper_grasp'>
        <grasp_check>
          <attach_steps>1</attach_steps>
          <detach_steps>1</detach_steps>
          <min_contact_count>3</min_contact_count>
        </grasp_check>
        <gripper_link>gripper_left_finger_link</gripper_link>
        <gripper_link>gripper_right_finger_link</gripper_link>
        <palm_link>arm_7_link</palm_link>
      </gripper>
      <pose>0 0 0 0 -0 0</pose>
    </model>
    <model name='table'>
      <static>1</static>
      <link name='link'>
        <collision name='surface'>
          <pose>0 0 0.6 0 -0 0</pose>
          <geometry>
            <box>
              <size>1 0.8 0.03</size>
            </box>
          </geometry>
          <max_contacts>10</max_contacts>
          <surface>
            <contact>
              <ode/>
            </contact>
            <bounce/>
            <friction>
              <torsional>
                <ode/>
              </torsional>
              <ode/>
            </friction>
          </surface>
        </collision>
        <visual name='visual1'>
          <pose>0 0 0.6 0 -0 0</pose>
          <geometry>
            <box>
              <size>1 0.8 0.03</size>
            </box>
          </geometry>
          <material>
            <script>
              <uri>file://media/materials/scripts/gazebo.material</uri>
              <name>Gazebo/Wood</name>
            </script>
          </material>
        </visual>
        <collision name='front_left_leg'>
          <pose>0.48 0.38 0.3 0 -0 0</pose>
          <geometry>
            <cylinder>
              <radius>0.02</radius>
              <length>0.6</length>
            </cylinder>
          </geometry>
          <max_contacts>10</max_contacts>
          <surface>
            <contact>
              <ode/>
            </contact>
            <bounce/>
            <friction>
              <torsional>
                <ode/>
              </torsional>
              <ode/>
            </friction>
          </surface>
        </collision>
        <visual name='front_left_leg'>
          <pose>0.48 0.38 0.3 0 -0 0</pose>
          <geometry>
            <cylinder>
              <radius>0.02</radius>
              <length>0.6</length>
            </cylinder>
          </geometry>
          <material>
            <script>
              <uri>file://media/materials/scripts/gazebo.material</uri>
              <name>Gazebo/Grey</name>
            </script>
          </material>
        </visual>
        <collision name='front_right_leg'>
          <pose>0.48 -0.38 0.3 0 -0 0</pose>
          <geometry>
            <cylinder>
              <radius>0.02</radius>
              <length>0.6</length>
            </cylinder>
          </geometry>
          <max_contacts>10</max_contacts>
          <surface>
            <contact>
              <ode/>
            </contact>
            <bounce/>
            <friction>
              <torsional>
                <ode/>
              </torsional>
              <ode/>
            </friction>
          </surface>
        </collision>
        <visual name='front_right_leg'>
          <pose>0.48 -0.38 0.3 0 -0 0</pose>
          <geometry>
            <cylinder>
              <radius>0.02</radius>
              <length>0.6</length>
            </cylinder>
          </geometry>
          <material>
            <script>
              <uri>file://media/materials/scripts/gazebo.material</uri>
              <name>Gazebo/Grey</name>
            </script>
          </material>
        </visual>
        <collision name='back_right_leg'>
          <pose>-0.48 -0.38 0.3 0 -0 0</pose>
          <geometry>
            <cylinder>
              <radius>0.02</radius>
              <length>0.6</length>
            </cylinder>
          </geometry>
          <max_contacts>10</max_contacts>
          <surface>
            <contact>
              <ode/>
            </contact>
            <bounce/>
            <friction>
              <torsional>
                <ode/>
              </torsional>
              <ode/>
            </friction>
          </surface>
        </collision>
        <visual name='back_right_leg'>
          <pose>-0.48 -0.38 0.3 0 -0 0</pose>
          <geometry>
            <cylinder>
              <radius>0.02</radius>
              <length>0.6</length>
            </cylinder>
          </geometry>
          <material>
            <script>
              <uri>file://media/materials/scripts/gazebo.material</uri>
              <name>Gazebo/Grey</name>
            </script>
          </material>
        </visual>
        <collision name='back_left_leg'>
          <pose>-0.48 0.38 0.3 0 -0 0</pose>
          <geometry>
            <cylinder>
              <radius>0.02</radius>
              <length>0.6</length>
            </cylinder>
          </geometry>
          <max_contacts>10</max_contacts>
          <surface>
            <contact>
              <ode/>
            </contact>
            <bounce/>
            <friction>
              <torsional>
                <ode/>
              </torsional>
              <ode/>
            </friction>
          </surface>
        </collision>
        <visual name='back_left_leg'>
          <pose>-0.48 0.38 0.3 0 -0 0</pose>
          <geometry>
            <cylinder>
              <radius>0.02</radius>
              <length>0.6</length>
            </cylinder>
          </geometry>
          <material>
            <script>
              <uri>file://media/materials/scripts/gazebo.material</uri>
              <name>Gazebo/Grey</name>
            </script>
          </material>
        </visual>
        <velocity_decay>
          <linear>0</linear>
          <angular>0</angular>
        </velocity_decay>
        <self_collide>0</self_collide>
        <kinematic>0</kinematic>
        <gravity>1</gravity>
        <enable_wind>0</enable_wind>
      </link>
      <pose>1.53482 -1.66284 0 0 -0 0</pose>
    </model>
    <model name='table_0'>
      <static>1</static>
      <link name='link'>
        <collision name='surface'>
          <pose>0 0 0.6 0 -0 0</pose>
          <geometry>
            <box>
              <size>1 0.8 0.03</size>
            </box>
          </geometry>
          <max_contacts>10</max_contacts>
          <surface>
            <contact>
              <ode/>
            </contact>
            <bounce/>
            <friction>
              <torsional>
                <ode/>
              </torsional>
              <ode/>
            </friction>
          </surface>
        </collision>
        <visual name='visual1'>
          <pose>0 0 0.6 0 -0 0</pose>
          <geometry>
            <box>
              <size>1 0.8 0.03</size>
            </box>
          </geometry>
          <material>
            <script>
              <uri>file://media/materials/scripts/gazebo.material</uri>
              <name>Gazebo/Wood</name>
            </script>
          </material>
        </visual>
        <collision name='front_left_leg'>
          <pose>0.48 0.38 0.3 0 -0 0</pose>
          <geometry>
            <cylinder>
              <radius>0.02</radius>
              <length>0.6</length>
            </cylinder>
          </geometry>
          <max_contacts>10</max_contacts>
          <surface>
            <contact>
              <ode/>
            </contact>
            <bounce/>
            <friction>
              <torsional>
                <ode/>
              </torsional>
              <ode/>
            </friction>
          </surface>
        </collision>
        <visual name='front_left_leg'>
          <pose>0.48 0.38 0.3 0 -0 0</pose>
          <geometry>
            <cylinder>
              <radius>0.02</radius>
              <length>0.6</length>
            </cylinder>
          </geometry>
          <material>
            <script>
              <uri>file://media/materials/scripts/gazebo.material</uri>
              <name>Gazebo/Grey</name>
            </script>
          </material>
        </visual>
        <collision name='front_right_leg'>
          <pose>0.48 -0.38 0.3 0 -0 0</pose>
          <geometry>
            <cylinder>
              <radius>0.02</radius>
              <length>0.6</length>
            </cylinder>
          </geometry>
          <max_contacts>10</max_contacts>
          <surface>
            <contact>
              <ode/>
            </contact>
            <bounce/>
            <friction>
              <torsional>
                <ode/>
              </torsional>
              <ode/>
            </friction>
          </surface>
        </collision>
        <visual name='front_right_leg'>
          <pose>0.48 -0.38 0.3 0 -0 0</pose>
          <geometry>
            <cylinder>
              <radius>0.02</radius>
              <length>0.6</length>
            </cylinder>
          </geometry>
          <material>
            <script>
              <uri>file://media/materials/scripts/gazebo.material</uri>
              <name>Gazebo/Grey</name>
            </script>
          </material>
        </visual>
        <collision name='back_right_leg'>
          <pose>-0.48 -0.38 0.3 0 -0 0</pose>
          <geometry>
            <cylinder>
              <radius>0.02</radius>
              <length>0.6</length>
            </cylinder>
          </geometry>
          <max_contacts>10</max_contacts>
          <surface>
            <contact>
              <ode/>
            </contact>
            <bounce/>
            <friction>
              <torsional>
                <ode/>
              </torsional>
              <ode/>
            </friction>
          </surface>
        </collision>
        <visual name='back_right_leg'>
          <pose>-0.48 -0.38 0.3 0 -0 0</pose>
          <geometry>
            <cylinder>
              <radius>0.02</radius>
              <length>0.6</length>
            </cylinder>
          </geometry>
          <material>
            <script>
              <uri>file://media/materials/scripts/gazebo.material</uri>
              <name>Gazebo/Grey</name>
            </script>
          </material>
        </visual>
        <collision name='back_left_leg'>
          <pose>-0.48 0.38 0.3 0 -0 0</pose>
          <geometry>
            <cylinder>
              <radius>0.02</radius>
              <length>0.6</length>
            </cylinder>
          </geometry>
          <max_contacts>10</max_contacts>
          <surface>
            <contact>
              <ode/>
            </contact>
            <bounce/>
            <friction>
              <torsional>
                <ode/>
              </torsional>
              <ode/>
            </friction>
          </surface>
        </collision>
        <visual name='back_left_leg'>
          <pose>-0.48 0.38 0.3 0 -0 0</pose>
          <geometry>
            <cylinder>
              <radius>0.02</radius>
              <length>0.6</length>
            </cylinder>
          </geometry>
          <material>
            <script>
              <uri>file://media/materials/scripts/gazebo.material</uri>
              <name>Gazebo/Grey</name>
            </script>
          </material>
        </visual>
        <velocity_decay>
          <linear>0</linear>
          <angular>0</angular>
        </velocity_decay>
        <self_collide>0</self_collide>
        <kinematic>0</kinematic>
        <gravity>1</gravity>
        <enable_wind>0</enable_wind>
      </link>
      <pose>1.49226 0.902799 0 0 -0 0</pose>
    </model>
    <state world_name='default'>
      <sim_time>3897 79000000</sim_time>
      <real_time>624 112182839</real_time>
      <wall_time>1709142477 28465384</wall_time>
      <iterations>403021</iterations>
      <model name='bowl'>
        <pose>0.600017 2.4e-05 0.614998 1.7e-05 1.5e-05 -9.6e-05</pose>
        <scale>1 1 1</scale>
        <link name='link'>
          <pose>0.600017 2.4e-05 0.614998 1.7e-05 1.5e-05 -9.6e-05</pose>
          <velocity>0 0 0 0 -0 0</velocity>
          <acceleration>0.912824 -0.998973 -7.58213 1.7631 0.588513 0.324584</acceleration>
          <wrench>0.091282 -0.099897 -0.758213 0 -0 0</wrench>
        </link>
      </model>
      <model name='ground_plane'>
        <pose>0 0 0 0 -0 0</pose>
        <scale>1 1 1</scale>
        <link name='link'>
          <pose>0 0 0 0 -0 0</pose>
          <velocity>0 0 0 0 -0 0</velocity>
          <acceleration>0 0 0 0 -0 0</acceleration>
          <wrench>0 0 0 0 -0 0</wrench>
        </link>
      </model>
      <model name='table'>
        <pose>0.92155 -0.139738 0 0 -0 0</pose>
        <scale>1 1 1</scale>
        <link name='link'>
          <pose>0.92155 -0.139738 0 0 -0 0</pose>
          <velocity>0 0 0 0 -0 0</velocity>
          <acceleration>0 0 0 0 -0 0</acceleration>
          <wrench>0 0 0 0 -0 0</wrench>
        </link>
      </model>
      <model name='table_0'>
        <pose>0.945103 1.45361 0 0 -0 0</pose>
        <scale>1 1 1</scale>
        <link name='link'>
          <pose>0.945103 1.45361 0 0 -0 0</pose>
          <velocity>0 0 0 0 -0 0</velocity>
          <acceleration>0 0 0 0 -0 0</acceleration>
          <wrench>0 0 0 0 -0 0</wrench>
        </link>
      </model>
      <model name='tiago'>
        <pose>-0.027371 2e-05 -0.000744 0.000614 0.000165 0.036511</pose>
        <scale>1 1 1</scale>
        <link name='arm_1_link'>
          <pose>0.065272 0.016869 0.884866 -0.000115 0.0006 -1.3343</pose>
          <velocity>-1e-06 0 -0 -1e-06 0 7e-06</velocity>
          <acceleration>-1e-05 2.7e-05 4e-06 -3.1247 -0.422199 -0.428471</acceleration>
          <wrench>-1.5e-05 4.2e-05 7e-06 0 -0 0</wrench>
        </link>
        <link name='arm_2_link'>
          <pose>0.113511 -0.100063 0.853791 1.5703 1.33726 -1.33479</pose>
          <velocity>-1e-06 1e-06 0 0 -0 7e-06</velocity>
          <acceleration>-1.1e-05 7e-06 -2e-06 -2.81224 -0.794177 2.44917</acceleration>
          <wrench>-2.1e-05 1.3e-05 -3e-06 0 -0 0</wrench>
        </link>
        <link name='arm_3_link'>
          <pose>0.119813 -0.119849 0.76672 0.046984 -0.228849 -1.53914</pose>
          <velocity>-0 1e-06 0 0 -2e-06 -3e-06</velocity>
          <acceleration>1.6e-05 -8.6e-05 2.5e-05 -0.759567 0.985939 0.473858</acceleration>
          <wrench>2.8e-05 -0.000154 4.4e-05 0 -0 0</wrench>
        </link>
        <link name='arm_4_link'>
          <pose>0.104263 -0.151473 0.544974 -1.52467 0.125676 -1.5227</pose>
          <velocity>-0 1e-06 0 5e-06 -2e-06 -3e-06</velocity>
          <acceleration>-9.2e-05 -0.000138 2e-06 1.13906 -0.031164 -2.60261</acceleration>
          <wrench>-0.000132 -0.000198 3e-06 0 -0 0</wrench>
        </link>
        <link name='arm_5_link'>
          <pose>0.124284 0.01275 0.546694 0.346729 -1.43712 -1.87231</pose>
          <velocity>0 1e-06 1e-06 5e-06 1e-06 -2e-06</velocity>
          <acceleration>-4.8e-05 -0.000128 -4e-06 2.27747 0.733326 3.11974</acceleration>
          <wrench>-4.5e-05 -0.00012 -3e-06 0 -0 0</wrench>
        </link>
        <link name='arm_6_link'>
          <pose>0.117129 0.161395 0.565495 1.03352 -1.48225 2.14869</pose>
          <velocity>1e-06 1e-06 2e-06 5e-06 -8e-06 0</velocity>
          <acceleration>-0.000319 -0.000133 -4.6e-05 -2.10852 -1.07205 -1.72179</acceleration>
          <wrench>-9.7e-05 -4e-05 -1.4e-05 0 -0 0</wrench>
        </link>
        <link name='arm_7_link'>
          <pose>0.117129 0.161395 0.565495 0.045419 -0.076039 -1.53185</pose>
          <velocity>1e-06 1e-06 2e-06 5e-06 -5e-06 -3e-06</velocity>
          <acceleration>0.000402 -8.2e-05 -1.4e-05 -0.05875 -0.039059 0.188805</acceleration>
          <wrench>0.000322 -6.6e-05 -1.1e-05 0 -0 0</wrench>
        </link>
        <link name='base_footprint'>
          <pose>-0.027371 2e-05 -0.000744 0.000614 0.000165 0.036511</pose>
          <velocity>1e-06 -0 2e-05 -1e-06 -3e-06 -1e-06</velocity>
          <acceleration>-0 8e-06 -1e-06 0.000618 5.4e-05 -0.00263</acceleration>
          <wrench>-1.6e-05 0.000329 -4.1e-05 0 -0 0</wrench>
        </link>
        <link name='caster_back_left_1_link'>
          <pose>-0.204467 0.095581 0.064435 0.00031 0.002857 -1.02672</pose>
          <velocity>1e-06 -1e-06 6.3e-05 0.00099 0.000529 0.000118</velocity>
          <acceleration>-1e-06 2e-06 -1e-06 0.005407 0.007512 0.001877</acceleration>
          <wrench>-0 0 -0 0 -0 0</wrench>
        </link>
        <link name='caster_back_left_2_link'>
          <pose>-0.21276 0.109312 0.024493 -1.56974 -1.28604 -1.02773</pose>
          <velocity>-3e-06 7e-06 8.8e-05 -0.000263 -0.000179 0.000114</velocity>
          <acceleration>-1e-06 1e-06 -1e-06 -2.9e-05 -3.3e-05 6e-06</acceleration>
          <wrench>-0 0 -0 0 -0 0</wrench>
        </link>
        <link name='caster_back_right_1_link'>
          <pose>-0.197021 -0.108282 0.064386 0.000282 0.004899 -1.19849</pose>
          <velocity>1e-06 -2e-06 0.000104 0.00209 0.000713 0.000109</velocity>
          <acceleration>2e-06 0 0 0.00646 0.007445 0.002496</acceleration>
          <wrench>0 0 0 0 -0 0</wrench>
        </link>
        <link name='caster_back_right_2_link'>
          <pose>-0.202851 -0.09332 0.024488 -1.57031 -1.02487 -1.19891</pose>
          <velocity>-3e-06 1.5e-05 0.000153 -0.000599 -0.000257 9.7e-05</velocity>
          <acceleration>0 -1e-06 -0 4.9e-05 -1e-06 0.000176</acceleration>
          <wrench>0 -0 -0 0 -0 0</wrench>
        </link>
        <link name='caster_front_left_1_link'>
          <pose>0.138305 0.108102 0.064413 -0.000376 0.003789 -1.70121</pose>
          <velocity>1e-06 -1e-06 8.1e-05 0.001617 -0.000168 -1.1e-05</velocity>
          <acceleration>-0 8e-06 -1e-06 -0.000999 -0.000703 -0.000435</acceleration>
          <wrench>-0 0 -0 0 -0 0</wrench>
        </link>
        <link name='caster_front_left_2_link'>
          <pose>0.140378 0.124016 0.024491 -1.57224 -1.31299 -1.69982</pose>
          <velocity>1e-06 1.2e-05 0.000118 -0.000549 9.1e-05 -8e-06</velocity>
          <acceleration>0 7e-06 -0 -0.000271 2.5e-05 -5.2e-05</acceleration>
          <wrench>0 1e-06 -0 0 -0 0</wrench>
        </link>
        <link name='caster_front_right_1_link'>
          <pose>0.145751 -0.095762 0.064364 -0.000131 0.00586 -1.51046</pose>
          <velocity>0 -2e-06 0.000122 0.002706 0.000156 0.000105</velocity>
          <acceleration>2e-06 6e-06 1e-06 0.008966 0.007473 0.003541</acceleration>
          <wrench>0 0 0 0 -0 0</wrench>
        </link>
        <link name='caster_front_right_2_link'>
          <pose>0.144778 -0.079724 0.024486 -1.57128 -1.29673 -1.51</pose>
          <velocity>-2e-06 2e-05 0.000183 -0.00092 -5.4e-05 0.000105</velocity>
          <acceleration>-1e-06 6e-06 0 -0.000248 -4.3e-05 0.000221</acceleration>
          <wrench>-0 1e-06 0 0 -0 0</wrench>
        </link>
        <link name='gripper_left_finger_link'>
          <pose>0.158547 0.168274 0.634558 -3.06548 0.045289 -3.0992</pose>
          <velocity>-3e-06 0 2e-06 5e-06 -5e-06 -3e-06</velocity>
          <acceleration>-0.000279 0.000229 -0.000505 -1.64773 -0.08423 -2.43678</acceleration>
          <wrench>-3.1e-05 2.5e-05 -5.6e-05 0 -0 0</wrench>
        </link>
        <link name='gripper_right_finger_link'>
          <pose>0.068963 0.164475 0.630494 -3.06548 0.045289 -3.09921</pose>
          <velocity>8e-06 1e-06 2e-06 5e-06 -6e-06 -4e-06</velocity>
          <acceleration>-0.000545 -0.000364 0.000322 0.002716 0.024753 0.059357</acceleration>
          <wrench>-6e-05 -4e-05 3.5e-05 0 -0 0</wrench>
        </link>
        <link name='head_1_link'>
          <pose>0.092743 0.00377 1.03585 0.000613 0.000165 0.035912</pose>
          <velocity>-2e-06 0 0 -1e-06 -3e-06 -5e-06</velocity>
          <acceleration>-9e-06 3.3e-05 1.7e-05 -0.90666 -0.538465 -1.00773</acceleration>
          <wrench>-5e-06 2.1e-05 1.1e-05 0 -0 0</wrench>
        </link>
        <link name='head_2_link'>
          <pose>0.097758 0.00389 1.13385 1.57141 0.006501 0.035916</pose>
          <velocity>-2e-06 1e-06 0 -1e-06 1.2e-05 -5e-06</velocity>
          <acceleration>-9e-06 2.8e-05 1.8e-05 2.16055 0.303133 2.01707</acceleration>
          <wrench>-8e-06 2.5e-05 1.6e-05 0 -0 0</wrench>
        </link>
        <link name='suspension_left_link'>
          <pose>-0.027353 -3.9e-05 0.096318 0.000614 0.000165 0.03651</pose>
          <velocity>0 -0 8.3e-05 -1e-06 -2e-06 -1e-06</velocity>
          <acceleration>1e-06 5e-06 3e-06 -2.4e-05 -9e-06 1.9e-05</acceleration>
          <wrench>8e-06 4.6e-05 2.5e-05 0 -0 0</wrench>
        </link>
        <link name='suspension_right_link'>
          <pose>-0.027353 -3.9e-05 0.096567 0.000614 0.000165 0.03651</pose>
          <velocity>0 -0 8.3e-05 -1e-06 -2e-06 -1e-06</velocity>
          <acceleration>1e-06 5e-06 -3e-06 -2.4e-05 -9e-06 1.9e-05</acceleration>
          <wrench>8e-06 4.6e-05 -2.5e-05 0 -0 0</wrench>
        </link>
        <link name='torso_lift_link'>
          <pose>-0.089136 -0.002873 1.03588 0.000614 0.000165 0.036511</pose>
          <velocity>-2e-06 1e-06 -0 -1e-06 -2e-06 -1e-06</velocity>
          <acceleration>-6e-06 2.3e-05 1.6e-05 0.001861 0.000964 0.008861</acceleration>
          <wrench>-4.3e-05 0.000159 0.000109 0 -0 0</wrench>
        </link>
        <link name='wheel_left_link'>
          <pose>-0.034734 0.202026 0.096443 -1.57015 -0.352044 0.036286</pose>
          <velocity>0 -0 8.2e-05 1e-06 5e-06 -1e-06</velocity>
          <acceleration>-3e-06 4e-06 -2e-06 0.000314 -0.009838 3.4e-05</acceleration>
          <wrench>-6e-06 8e-06 -4e-06 0 -0 0</wrench>
        </link>
        <link name='wheel_right_link'>
          <pose>-0.019972 -0.202104 0.096443 -1.57017 -0.202132 0.036385</pose>
          <velocity>0 -0 8.3e-05 1e-06 2e-06 -1e-06</velocity>
          <acceleration>5e-06 5e-06 2e-06 0.000191 -0.006471 3.3e-05</acceleration>
          <wrench>8e-06 8e-06 4e-06 0 -0 0</wrench>
        </link>
      </model>
      <light name='sun'>
        <pose>0 0 10 0 -0 0</pose>
      </light>
    </state>
    <gui fullscreen='0'>
      <camera name='user_camera'>
        <pose>1.57085 -2.5592 3.0323 -0 0.651643 1.95619</pose>
        <view_controller>orbit</view_controller>
        <projection_type>perspective</projection_type>
      </camera>
    </gui>
    <model name='bowl'>
      <link name='link'>
        <inertial>
          <pose>0 0 0.0175 0 -0 0</pose>
          <mass>0.1</mass>
          <inertia>
            <ixx>0.000250308</ixx>
            <ixy>0</ixy>
            <ixz>0</ixz>
            <iyy>0.000250308</iyy>
            <iyz>0</iyz>
            <izz>0.0004802</izz>
          </inertia>
        </inertial>
        <collision name='collision'>
          <pose>0 0 0.0175 0 -0 0</pose>
          <geometry>
            <cylinder>
              <radius>0.098</radius>
              <length>0.035</length>
            </cylinder>
          </geometry>
          <max_contacts>10</max_contacts>
          <surface>
            <contact>
              <ode/>
            </contact>
            <bounce/>
            <friction>
              <torsional>
                <ode/>
              </torsional>
              <ode/>
            </friction>
          </surface>
        </collision>
        <visual name='visual'>
          <geometry>
            <mesh>
              <uri>model://bowl/meshes/bowl.dae</uri>
            </mesh>
          </geometry>
        </visual>
        <self_collide>0</self_collide>
        <enable_wind>0</enable_wind>
        <kinematic>0</kinematic>
      </link>
      <pose>0.688389 -0.336209 0 0 -0 0</pose>
    </model>
  </world>
</sdf>
